Workbook

Sheet T1_HBW_TotPers
D4: - - - - - Table 1a - 2020 Home-Based Work (HBW) Person Trips - - - - -
B5: District Names | E5: Destination District
E6: 1 | F6: 2 | G6: 3 | H6: 4 | I6: 5 | J6: 6 | K6: 7 | L6: 8 | M6: 9 | N6: 10 | O6: 11 | P6: 12 | Q6: 13 | R6: 14 | S6: 15 | T6: 16 | U6: 17 | V6: 18 | W6: 19 | X6: 20 | Y6: 21 | Z6: 22 | AA6: 23 | AB6: 24 | AC6: 25 | AD6: 26 | AE6: 27 | AF6: 28 | AG6: 29 | AH6: 30 | AI6: 31 | AJ6: 32 | AK6: 33 | AL6: 34 | AM6: 35 | AN6: 36 | AO6: 37 | AP6: 38 | AQ6: 39 | AR6: 40 | AS6: 41 | AT6: 42 | AU6: 43 | AV6: 44 | AW6: Total
B7: Pittsburgh Chateau Area | C7: Origin District | D7: 1 | E7: 580 | F7: 443 | G7: 190 | H7: 122 | I7: 231 | J7: 11 | K7: 18 | L7: 294 | M7: 88 | N7: 15 | O7: 4 | P7: 1721 | Q7: 15 | R7: 65 | S7: 116 | T7: 0 | U7: 6 | V7: 0 | W7: 6 | X7: 12 | Y7: 3 | Z7: 0 | AA7: 0 | AB7: 0 | AC7: 2 | AD7: 13 | AE7: 0 | AF7: 339 | AG7: 0 | AH7: 0 | AI7: 1 | AJ7: 2 | AK7: 3 | AL7: 0 | AM7: 0 | AN7: 0 | AO7: 0 | AP7: 3 | AQ7: 0 | AR7: 118 | AS7: 3 | AT7: 13 | AU7: 259 | AV7: 162 | AW7: =SUM(E7:AV7) -> 4858
B8: Pittsburgh Lower North Side | D8: 2 | E8: 264 | F8: 480 | G8: 119 | H8: 29 | I8: 142 | J8: 7 | K8: 15 | L8: 268 | M8: 73 | N8: 19 | O8: 3 | P8: 1600 | Q8: 20 | R8: 80 | S8: 139 | T8: 0 | U8: 5 | V8: 0 | W8: 6 | X8: 9 | Y8: 0 | Z8: 0 | AA8: 0 | AB8: 0 | AC8: 0 | AD8: 5 | AE8: 0 | AF8: 106 | AG8: 0 | AH8: 0 | AI8: 0 | AJ8: 0 | AK8: 2 | AL8: 0 | AM8: 0 | AN8: 0 | AO8: 0 | AP8: 2 | AQ8: 1 | AR8: 115 | AS8: 3 | AT8: 14 | AU8: 148 | AV8: 87 | AW8: =SUM(E8:AV8) -> 3761
B9: Pittsburgh Upper North Side | D9: 3 | E9: 1000 | F9: 1196 | G9: 764 | H9: 359 | I9: 1132 | J9: 29 | K9: 60 | L9: 973 | M9: 244 | N9: 74 | O9: 11 | P9: 4994 | Q9: 66 | R9: 264 | S9: 472 | T9: 2 | U9: 17 | V9: 1 | W9: 14 | X9: 39 | Y9: 5 | Z9: 0 | AA9: 0 | AB9: 0 | AC9: 4 | AD9: 21 | AE9: 2 | AF9: 810 | AG9: 0 | AH9: 0 | AI9: 1 | AJ9: 3 | AK9: 14 | AL9: 0 | AM9: 0 | AN9: 0 | AO9: 0 | AP9: 9 | AQ9: 1 | AR9: 377 | AS9: 9 | AT9: 48 | AU9: 553 | AV9: 320 | AW9: =SUM(E9:AV9) -> 13888
B10: Allegheny County Northwest | D10: 4 | E10: 1100 | F10: 820 | G10: 499 | H10: 7647 | I10: 2992 | J10: 32 | K10: 56 | L10: 895 | M10: 245 | N10: 57 | O10: 11 | P10: 4342 | Q10: 50 | R10: 174 | S10: 314 | T10: 3 | U10: 11 | V10: 0 | W10: 11 | X10: 41 | Y10: 2 | Z10: 0 | AA10: 0 | AB10: 0 | AC10: 3 | AD10: 20 | AE10: 1 | AF10: 5294 | AG10: 0 | AH10: 0 | AI10: 141 | AJ10: 405 | AK10: 162 | AL10: 0 | AM10: 0 | AN10: 0 | AO10: 0 | AP10: 75 | AQ10: 0 | AR10: 305 | AS10: 5 | AT10: 36 | AU10: 792 | AV10: 565 | AW10: =SUM(E10:AV10) -> 27106
B11: Allegheny County North (remainder) | D11: 5 | E11: 3047 | F11: 4592 | G11: 2626 | H11: 3879 | I11: 110710 | J11: 186 | K11: 797 | L11: 9007 | M11: 1200 | N11: 1144 | O11: 115 | P11: 24002 | Q11: 1725 | R11: 1477 | S11: 5868 | T11: 11 | U11: 1821 | V11: 299 | W11: 1000 | X11: 678 | Y11: 60 | Z11: 7 | AA11: 0 | AB11: 0 | AC11: 24 | AD11: 63 | AE11: 0 | AF11: 4685 | AG11: 30 | AH11: 60 | AI11: 81 | AJ11: 305 | AK11: 3635 | AL11: 0 | AM11: 0 | AN11: 1 | AO11: 1 | AP11: 18 | AQ11: 1646 | AR11: 1895 | AS11: 431 | AT11: 2533 | AU11: 2224 | AV11: 1354 | AW11: =SUM(E11:AV11) -> 193237
B12: Hazelwood | D12: 6 | E12: 77 | F12: 110 | G12: 34 | H12: 14 | I12: 84 | J12: 352 | K12: 231 | L12: 1062 | M12: 315 | N12: 93 | O12: 91 | P12: 1542 | Q12: 69 | R12: 52 | S12: 158 | T12: 18 | U12: 17 | V12: 1 | W12: 23 | X12: 88 | Y12: 6 | Z12: 6 | AA12: 2 | AB12: 0 | AC12: 26 | AD12: 72 | AE12: 7 | AF12: 66 | AG12: 0 | AH12: 0 | AI12: 0 | AJ12: 0 | AK12: 0 | AL12: 0 | AM12: 0 | AN12: 0 | AO12: 0 | AP12: 1 | AQ12: 1 | AR12: 176 | AS12: 10 | AT12: 62 | AU12: 161 | AV12: 72 | AW12: =SUM(E12:AV12) -> 5099
B13: Squirrel Hill | D13: 7 | E13: 291 | F13: 372 | G13: 123 | H13: 41 | I13: 479 | J13: 380 | K13: 2024 | L13: 5698 | M13: 649 | N13: 825 | O13: 255 | P13: 4669 | Q13: 651 | R13: 191 | S13: 1202 | T13: 25 | U13: 145 | V13: 10 | W13: 115 | X13: 688 | Y13: 32 | Z13: 18 | AA13: 2 | AB13: 1 | AC13: 68 | AD13: 91 | AE13: 6 | AF13: 234 | AG13: 0 | AH13: 0 | AI13: 0 | AJ13: 0 | AK13: 0 | AL13: 0 | AM13: 0 | AN13: 0 | AO13: 0 | AP13: 0 | AQ13: 11 | AR13: 515 | AS13: 86 | AT13: 641 | AU13: 423 | AV13: 231 | AW13: =SUM(E13:AV13) -> 21192
B14: Oakland | D14: 8 | E14: 125 | F14: 169 | G14: 56 | H14: 19 | I14: 138 | J14: 67 | K14: 208 | L14: 3608 | M14: 278 | N14: 166 | O14: 32 | P14: 2252 | Q14: 110 | R14: 84 | S14: 408 | T14: 7 | U14: 19 | V14: 0 | W14: 19 | X14: 73 | Y14: 4 | Z14: 1 | AA14: 1 | AB14: 0 | AC14: 10 | AD14: 15 | AE14: 5 | AF14: 92 | AG14: 0 | AH14: 0 | AI14: 0 | AJ14: 0 | AK14: 1 | AL14: 0 | AM14: 0 | AN14: 0 | AO14: 0 | AP14: 1 | AQ14: 1 | AR14: 298 | AS14: 17 | AT14: 88 | AU14: 182 | AV14: 91 | AW14: =SUM(E14:AV14) -> 8645
B15: South Side | D15: 9 | E15: 147 | F15: 212 | G15: 64 | H15: 20 | I15: 115 | J15: 65 | K15: 77 | L15: 1196 | M15: 888 | N15: 55 | O15: 29 | P15: 2805 | Q15: 39 | R15: 90 | S15: 219 | T15: 6 | U15: 9 | V15: 0 | W15: 11 | X15: 44 | Y15: 5 | Z15: 2 | AA15: 1 | AB15: 0 | AC15: 8 | AD15: 48 | AE15: 7 | AF15: 141 | AG15: 0 | AH15: 0 | AI15: 0 | AJ15: 0 | AK15: 0 | AL15: 0 | AM15: 0 | AN15: 0 | AO15: 0 | AP15: 1 | AQ15: 1 | AR15: 388 | AS15: 6 | AT15: 31 | AU15: 501 | AV15: 160 | AW15: =SUM(E15:AV15) -> 7391
B16: Shadyside | D16: 10 | E16: 85 | F16: 151 | G16: 65 | H16: 13 | I16: 248 | J16: 49 | K16: 308 | L16: 2521 | M16: 123 | N16: 588 | O16: 35 | P16: 1591 | Q16: 403 | R16: 109 | S16: 846 | T16: 3 | U16: 52 | V16: 3 | W16: 25 | X16: 132 | Y16: 6 | Z16: 4 | AA16: 0 | AB16: 0 | AC16: 7 | AD16: 15 | AE16: 1 | AF16: 55 | AG16: 0 | AH16: 0 | AI16: 0 | AJ16: 0 | AK16: 0 | AL16: 0 | AM16: 0 | AN16: 0 | AO16: 0 | AP16: 0 | AQ16: 4 | AR16: 177 | AS16: 54 | AT16: 261 | AU16: 103 | AV16: 55 | AW16: =SUM(E16:AV16) -> 8092
B17: Waterfront (West Homestead Homestead Munhall(part)) | D17: 11 | E17: 57 | F17: 75 | G17: 20 | H17: 8 | I17: 74 | J17: 116 | K17: 190 | L17: 622 | M17: 147 | N17: 72 | O17: 678 | P17: 882 | Q17: 57 | R17: 31 | S17: 115 | T17: 33 | U17: 24 | V17: 2 | W17: 40 | X17: 200 | Y17: 27 | Z17: 28 | AA17: 4 | AB17: 1 | AC17: 152 | AD17: 114 | AE17: 13 | AF17: 51 | AG17: 0 | AH17: 0 | AI17: 0 | AJ17: 0 | AK17: 0 | AL17: 0 | AM17: 0 | AN17: 0 | AO17: 0 | AP17: 2 | AQ17: 5 | AR17: 85 | AS17: 9 | AT17: 57 | AU17: 142 | AV17: 77 | AW17: =SUM(E17:AV17) -> 4210
B18: Downtown | D18: 12 | E18: 60 | F18: 99 | G18: 24 | H18: 8 | I18: 41 | J18: 7 | K18: 10 | L18: 204 | M18: 52 | N18: 14 | O18: 3 | P18: 1088 | Q18: 8 | R18: 37 | S18: 68 | T18: 2 | U18: 2 | V18: 0 | W18: 0 | X18: 8 | Y18: 0 | Z18: 0 | AA18: 0 | AB18: 0 | AC18: 0 | AD18: 5 | AE18: 2 | AF18: 37 | AG18: 0 | AH18: 0 | AI18: 0 | AJ18: 0 | AK18: 0 | AL18: 0 | AM18: 0 | AN18: 0 | AO18: 0 | AP18: 0 | AQ18: 0 | AR18: 93 | AS18: 2 | AT18: 6 | AU18: 70 | AV18: 35 | AW18: =SUM(E18:AV18) -> 1985
B19: East Liberty | D19: 13 | E19: 39 | F19: 68 | G19: 33 | H19: 5 | I19: 194 | J19: 19 | K19: 120 | L19: 800 | M19: 48 | N19: 177 | O19: 13 | P19: 666 | Q19: 340 | R19: 48 | S19: 405 | T19: 3 | U19: 38 | V19: 1 | W19: 13 | X19: 71 | Y19: 5 | Z19: 1 | AA19: 1 | AB19: 0 | AC19: 3 | AD19: 7 | AE19: 0 | AF19: 24 | AG19: 0 | AH19: 0 | AI19: 0 | AJ19: 0 | AK19: 0 | AL19: 0 | AM19: 0 | AN19: 0 | AO19: 0 | AP19: 0 | AQ19: 0 | AR19: 73 | AS19: 51 | AT19: 172 | AU19: 42 | AV19: 25 | AW19: =SUM(E19:AV19) -> 3505
... B50: Allegheny County Southcentral | D50: 44 | E50: 1421 | F50: 1626 | G50: 456 | H50: 352 | I50: 831 | J50: 231 | K50: 270 | L50: 3440 | M50: 1309 | N50: 189 | O50: 277 | P50: 14127 | Q50: 158 | R50: 483 | S50: 864 | T50: 70 | U50: 27 | V50: 0 | W50: 28 | X50: 212 | Y50: 22 | Z50: 81 | AA50: 21 | AB50: 19 | AC50: 166 | AD50: 3278 | AE50: 1508 | AF50: 12960 | AG50: 0 | AH50: 0 | AI50: 6 | AJ50: 6 | AK50: 1 | AL50: 0 | AM50: 0 | AN50: 0 | AO50: 0 | AP50: 4983 | AQ50: 9 | AR50: 1071 | AS50: 26 | AT50: 130 | AU50: 6438 | AV50: 44414 | AW50: =SUM(E50:AV50) -> 101510
D51: Total | E51: =SUM(E7:E50) -> 14841 | F51: =SUM(F7:F50) -> 17909 | G51: =SUM(G7:G50) -> 7757 | H51: =SUM(H7:H50) -> 22707 | I51: =SUM(I7:I50) -> 173782 | J51: =SUM(J7:J50) -> 4892 | K51: =SUM(K7:K50) -> 11648 | L51: =SUM(L7:L50) -> 71152 | ... AV51: =SUM(AV7:AV50) -> 82032 | AW51: =SUM(E51:AV51) -> 1880813
D60: - - - - - Table 1b - 2045 Home-Based Work (HBW) Person Trips - - - - -
B61: District Names | E61: Destination District
E62: 1 | F62: 2 | G62: 3 | H62: 4 | I62: 5 | J62: 6 | K62: 7 | L62: 8 | M62: 9 | N62: 10 | O62: 11 | P62: 12 | Q62: 13 | R62: 14 | S62: 15 | T62: 16 | U62: 17 | V62: 18 | W62: 19 | X62: 20 | Y62: 21 | Z62: 22 | AA62: 23 | AB62: 24 | AC62: 25 | AD62: 26 | AE62: 27 | AF62: 28 | AG62: 29 | AH62: 30 | AI62: 31 | AJ62: 32 | AK62: 33 | AL62: 34 | AM62: 35 | AN62: 36 | AO62: 37 | AP62: 38 | AQ62: 39 | AR62: 40 | AS62: 41 | AT62: 42 | AU62: 43 | AV62: 44 | AW62: Total
B63: Pittsburgh Chateau Area | C63: Origin District | D63: 1 | E63: 660 | F63: 481 | G63: 212 | H63: 124 | I63: 211 | J63: 34 | K63: 22 | L63: 327 | M63: 105 | N63: 18 | O63: 4 | P63: 2147 | Q63: 16 | R63: 98 | S63: 118 | T63: 1 | U63: 1 | V63: 0 | W63: 6 | X63: 14 | Y63: 0 | Z63: 0 | AA63: 0 | AB63: 0 | AC63: 1 | AD63: 11 | AE63: 1 | AF63: 310 | AG63: 0 | AH63: 0 | AI63: 0 | AJ63: 1 | AK63: 2 | AL63: 0 | AM63: 0 | AN63: 0 | AO63: 0 | AP63: 1 | AQ63: 0 | AR63: 159 | AS63: 4 | AT63: 12 | AU63: 292 | AV63: 160 | AW63: =SUM(E63:AV63) -> 5553
B64: Pittsburgh Lower North Side | D64: 2 | E64: 274 | F64: 496 | G64: 133 | H64: 26 | I64: 120 | J64: 24 | K64: 15 | L64: 269 | M64: 80 | N64: 17 | O64: 3 | P64: 1946 | Q64: 22 | R64: 110 | S64: 135 | T64: 0 | U64: 6 | V64: 0 | W64: 2 | X64: 8 | Y64: 0 | Z64: 0 | AA64: 0 | AB64: 0 | AC64: 2 | AD64: 8 | AE64: 0 | AF64: 94 | AG64: 0 | AH64: 0 | AI64: 0 | AJ64: 0 | AK64: 1 | AL64: 0 | AM64: 0 | AN64: 0 | AO64: 0 | AP64: 2 | AQ64: 0 | AR64: 150 | AS64: 4 | AT64: 14 | AU64: 158 | AV64: 72 | AW64: =SUM(E64:AV64) -> 4191
B65: Pittsburgh Upper North Side | D65: 3 | E65: 1066 | F65: 1210 | G65: 851 | H65: 355 | I65: 1042 | J65: 82 | K65: 60 | L65: 980 | M65: 257 | N65: 68 | O65: 13 | P65: 5878 | Q65: 70 | R65: 359 | S65: 470 | T65: 1 | U65: 13 | V65: 0 | W65: 11 | X65: 29 | Y65: 2 | Z65: 0 | AA65: 0 | AB65: 0 | AC65: 4 | AD65: 20 | AE65: 0 | AF65: 737 | AG65: 0 | AH65: 0 | AI65: 1 | AJ65: 2 | AK65: 7 | AL65: 0 | AM65: 0 | AN65: 0 | AO65: 0 | AP65: 5 | AQ65: 0 | AR65: 470 | AS65: 13 | AT65: 48 | AU65: 589 | AV65: 295 | AW65: =SUM(E65:AV65) -> 15008
B66: Allegheny County Northwest | D66: 4 | E66: 1231 | F66: 876 | G66: 571 | H66: 8234 | I66: 2813 | J66: 86 | K66: 69 | L66: 981 | M66: 286 | N66: 52 | O66: 12 | P66: 5468 | Q66: 50 | R66: 246 | S66: 330 | T66: 3 | U66: 9 | V66: 0 | W66: 6 | X66: 32 | Y66: 0 | Z66: 0 | AA66: 0 | AB66: 0 | AC66: 4 | AD66: 22 | AE66: 1 | AF66: 5491 | AG66: 0 | AH66: 0 | AI66: 148 | AJ66: 366 | AK66: 93 | AL66: 0 | AM66: 0 | AN66: 0 | AO66: 0 | AP66: 66 | AQ66: 0 | AR66: 415 | AS66: 10 | AT66: 37 | AU66: 906 | AV66: 594 | AW66: =SUM(E66:AV66) -> 29508
B67: Allegheny County North (remainder) | D67: 5 | E67: 3557 | F67: 5154 | G67: 3272 | H67: 4477 | I67: 128135 | J67: 554 | K67: 990 | L67: 9797 | M67: 1404 | N67: 1252 | O67: 101 | P67: 31616 | Q67: 2139 | R67: 2268 | S67: 7038 | T67: 9 | U67: 2122 | V67: 344 | W67: 921 | X67: 711 | Y67: 54 | Z67: 8 | AA67: 0 | AB67: 0 | AC67: 41 | AD67: 43 | AE67: 0 | AF67: 5233 | AG67: 29 | AH67: 77 | AI67: 93 | AJ67: 345 | AK67: 3509 | AL67: 0 | AM67: 0 | AN67: 0 | AO67: 0 | AP67: 11 | AQ67: 1754 | AR67: 2656 | AS67: 560 | AT67: 3121 | AU67: 2665 | AV67: 1359 | AW67: =SUM(E67:AV67) -> 227419
B68: Hazelwood | D68: 6 | E68: 75 | F68: 107 | G68: 29 | H68: 12 | I68: 75 | J68: 1731 | K68: 308 | L68: 1685 | M68: 316 | N68: 103 | O68: 100 | P68: 1820 | Q68: 85 | R68: 64 | S68: 196 | T68: 24 | U68: 20 | V68: 1 | W68: 20 | X68: 99 | Y68: 7 | Z68: 6 | AA68: 1 | AB68: 1 | AC68: 23 | AD68: 83 | AE68: 7 | AF68: 48 | AG68: 0 | AH68: 0 | AI68: 0 | AJ68: 0 | AK68: 0 | AL68: 0 | AM68: 0 | AN68: 0 | AO68: 0 | AP68: 0 | AQ68: 2 | AR68: 237 | AS68: 13 | AT68: 76 | AU68: 169 | AV68: 70 | AW68: =SUM(E68:AV68) -> 7613
B69: Squirrel Hill | D69: 7 | E69: 273 | F69: 344 | G69: 122 | H69: 37 | I69: 408 | J69: 1143 | K69: 2434 | L69: 6637 | M69: 705 | N69: 845 | O69: 263 | P69: 5343 | Q69: 747 | R69: 246 | S69: 1340 | T69: 17 | U69: 142 | V69: 7 | W69: 100 | X69: 711 | Y69: 27 | Z69: 17 | AA69: 1 | AB69: 0 | AC69: 70 | AD69: 76 | AE69: 11 | AF69: 171 | AG69: 0 | AH69: 0 | AI69: 0 | AJ69: 0 | AK69: 0 | AL69: 0 | AM69: 0 | AN69: 0 | AO69: 0 | AP69: 0 | AQ69: 11 | AR69: 760 | AS69: 101 | AT69: 727 | AU69: 435 | AV69: 192 | AW69: =SUM(E69:AV69) -> 24463
B70: Oakland | D70: 8 | E70: 107 | F70: 149 | G70: 53 | H70: 12 | I70: 112 | J70: 239 | K70: 221 | L70: 3750 | M70: 321 | N70: 163 | O70: 27 | P70: 2540 | Q70: 116 | R70: 105 | S70: 435 | T70: 1 | U70: 16 | V70: 1 | W70: 15 | X70: 64 | Y70: 1 | Z70: 2 | AA70: 1 | AB70: 0 | AC70: 8 | AD70: 12 | AE70: 3 | AF70: 64 | AG70: 0 | AH70: 0 | AI70: 0 | AJ70: 0 | AK70: 0 | AL70: 0 | AM70: 0 | AN70: 0 | AO70: 0 | AP70: 1 | AQ70: 0 | AR70: 436 | AS70: 16 | AT70: 92 | AU70: 172 | AV70: 78 | AW70: =SUM(E70:AV70) -> 9333
B71: South Side | D71: 9 | E71: 138 | F71: 191 | G71: 58 | H71: 16 | I71: 84 | J71: 179 | K71: 88 | L71: 1366 | M71: 987 | N71: 48 | O71: 24 | P71: 3246 | Q71: 39 | R71: 115 | S71: 212 | T71: 5 | U71: 8 | V71: 0 | W71: 9 | X71: 34 | Y71: 3 | Z71: 2 | AA71: 1 | AB71: 0 | AC71: 9 | AD71: 46 | AE71: 1 | AF71: 107 | AG71: 0 | AH71: 0 | AI71: 0 | AJ71: 0 | AK71: 0 | AL71: 0 | AM71: 0 | AN71: 0 | AO71: 0 | AP71: 2 | AQ71: 0 | AR71: 520 | AS71: 5 | AT71: 30 | AU71: 531 | AV71: 146 | AW71: =SUM(E71:AV71) -> 8250
B72: Shadyside | D72: 10 | E72: 84 | F72: 144 | G72: 68 | H72: 9 | I72: 213 | J72: 149 | K72: 359 | L72: 2562 | M72: 150 | N72: 614 | O72: 28 | P72: 1918 | Q72: 463 | R72: 149 | S72: 968 | T72: 2 | U72: 49 | V72: 3 | W72: 23 | X72: 131 | Y72: 5 | Z72: 4 | AA72: 0 | AB72: 0 | AC72: 7 | AD72: 15 | AE72: 1 | AF72: 44 | AG72: 0 | AH72: 0 | AI72: 0 | AJ72: 0 | AK72: 0 | AL72: 0 | AM72: 0 | AN72: 0 | AO72: 0 | AP72: 0 | AQ72: 3 | AR72: 263 | AS72: 63 | AT72: 296 | AU72: 107 | AV72: 48 | AW72: =SUM(E72:AV72) -> 8942
B73: Waterfront (West Homestead Homestead Munhall(part)) | D73: 11 | E73: 41 | F73: 54 | G73: 19 | H73: 7 | I73: 53 | J73: 314 | K73: 193 | L73: 733 | M73: 159 | N73: 60 | O73: 693 | P73: 710 | Q73: 54 | R73: 26 | S73: 107 | T73: 33 | U73: 28 | V73: 3 | W73: 50 | X73: 259 | Y73: 28 | Z73: 25 | AA73: 2 | AB73: 1 | AC73: 148 | AD73: 118 | AE73: 14 | AF73: 31 | AG73: 0 | AH73: 0 | AI73: 0 | AJ73: 0 | AK73: 0 | AL73: 0 | AM73: 0 | AN73: 0 | AO73: 0 | AP73: 1 | AQ73: 6 | AR73: 104 | AS73: 8 | AT73: 61 | AU73: 145 | AV73: 68 | AW73: =SUM(E73:AV73) -> 4356
B74: Downtown | D74: 12 | E74: 82 | F74: 141 | G74: 42 | H74: 10 | I74: 47 | J74: 27 | K74: 17 | L74: 312 | M74: 86 | N74: 17 | O74: 5 | P74: 1966 | Q74: 14 | R74: 79 | S74: 97 | T74: 2 | U74: 1 | V74: 0 | W74: 4 | X74: 8 | Y74: 0 | Z74: 0 | AA74: 0 | AB74: 0 | AC74: 0 | AD74: 3 | AE74: 0 | AF74: 44 | AG74: 0 | AH74: 0 | AI74: 0 | AJ74: 0 | AK74: 1 | AL74: 0 | AM74: 0 | AN74: 0 | AO74: 0 | AP74: 0 | AQ74: 0 | AR74: 180 | AS74: 3 | AT74: 11 | AU74: 108 | AV74: 48 | AW74: =SUM(E74:AV74) -> 3355
B75: East Liberty | D75: 13 | E75: 39 | F75: 67 | G75: 30 | H75: 6 | I75: 162 | J75: 53 | K75: 135 | L75: 849 | M75: 56 | N75: 181 | O75: 12 | P75: 769 | Q75: 372 | R75: 69 | S75: 453 | T75: 2 | U75: 36 | V75: 1 | W75: 14 | X75: 65 | Y75: 1 | Z75: 2 | AA75: 0 | AB75: 0 | AC75: 2 | AD75: 7 | AE75: 0 | AF75: 19 | AG75: 0 | AH75: 0 | AI75: 0 | AJ75: 0 | AK75: 1 | AL75: 0 | AM75: 0 | AN75: 0 | AO75: 0 | AP75: 0 | AQ75: 2 | AR75: 97 | AS75: 59 | AT75: 188 | AU75: 44 | AV75: 20 | AW75: =SUM(E75:AV75) -> 3813
... B106: Allegheny County Southcentral | D106: 44 | E106: 1445 | F106: 1560 | G106: 441 | H106: 311 | I106: 595 | J106: 757 | K106: 279 | L106: 3586 | M106: 1431 | N106: 157 | O106: 281 | P106: 15750 | Q106: 137 | R106: 596 | S106: 774 | T106: 75 | U106: 22 | V106: 0 | W106: 55 | X106: 196 | Y106: 33 | Z106: 69 | AA106: 24 | AB106: 18 | AC106: 153 | AD106: 3611 | AE106: 1546 | AF106: 12858 | AG106: 0 | AH106: 0 | AI106: 5 | AJ106: 3 | AK106: 1 | AL106: 3 | AM106: 0 | AN106: 0 | AO106: 0 | AP106: 4453 | AQ106: 9 | AR106: 1292 | AS106: 24 | AT106: 106 | AU106: 7353 | AV106: 49792 | AW106: =SUM(E106:AV106) -> 109801
D107: Total | E107: =SUM(E63:E106) -> 15733 | F107: =SUM(F63:F106) -> 18243 | G107: =SUM(G63:G106) -> 8861 | H107: =SUM(H63:H106) -> 25612 | I107: =SUM(I63:I106) -> 196183 | J107: =SUM(J63:J106) -> 15335 | K107: =SUM(K63:K106) -> 13344 | L107: =SUM(L63:L106) -> 77036 | ... AV107: =SUM(AV63:AV106) -> 91588 | AW107: =SUM(E107:AV107) -> 2085971
D116: - - - - - Table 1c - Change - 2020 To 2045 - Home-Based Work (HBW) Person Trips - - - - -
B117: District Names | E117: Destination District
E118: 1 | F118: 2 | G118: 3 | H118: 4 | I118: 5 | J118: 6 | K118: 7 | L118: 8 | M118: 9 | N118: 10 | O118: 11 | P118: 12 | Q118: 13 | R118: 14 | S118: 15 | T118: 16 | U118: 17 | V118: 18 | W118: 19 | X118: 20 | Y118: 21 | Z118: 22 | AA118: 23 | AB118: 24 | AC118: 25 | AD118: 26 | AE118: 27 | AF118: 28 | AG118: 29 | AH118: 30 | AI118: 31 | AJ118: 32 | AK118: 33 | AL118: 34 | AM118: 35 | AN118: 36 | AO118: 37 | AP118: 38 | AQ118: 39 | AR118: 40 | AS118: 41 | AT118: 42 | AU118: 43 | AV118: 44 | AW118: Total
B119: Pittsburgh Chateau Area | C119: Origin District | D119: 1 | E119: =E63-E7 -> 80 | F119: =F63-F7 -> 38 | G119: =G63-G7 -> 22 | H119: =H63-H7 -> 2 | I119: =I63-I7 -> -20 | J119: =J63-J7 -> 23 | K119: =K63-K7 -> 4 | L119: =L63-L7 -> 33 | ... AV119: =AV63-AV7 -> -2 | AW119: =SUM(E119:AV119) -> 695
...

Sheet T2_HBO_TotPers
D4: - - - - - Table 2a - 2020 Home-Based Other (HBO) Person Trips - - - - -
B5: District Names | E5: Destination District
E6: 1 | F6: 2 | G6: 3 | H6: 4 | I6: 5 | J6: 6 | K6: 7 | L6: 8 | M6: 9 | N6: 10 | O6: 11 | P6: 12 | Q6: 13 | R6: 14 | S6: 15 | T6: 16 | U6: 17 | V6: 18 | W6: 19 | X6: 20 | Y6: 21 | Z6: 22 | AA6: 23 | AB6: 24 | AC6: 25 | AD6: 26 | AE6: 27 | AF6: 28 | AG6: 29 | AH6: 30 | AI6: 31 | AJ6: 32 | AK6: 33 | AL6: 34 | AM6: 35 | AN6: 36 | AO6: 37 | AP6: 38 | AQ6: 39 | AR6: 40 | AS6: 41 | AT6: 42 | AU6: 43 | AV6: 44 | AW6: Total
B7: Pittsburgh Chateau Area | C7: Origin District | D7: 1 | E7: 1892 | F7: 1166 | G7: 636 | H7: 1031 | I7: 1500 | J7: 18 | K7: 60 | L7: 563 | M7: 238 | N7: 47 | O7: 47 | P7: 1490 | Q7: 37 | R7: 174 | S7: 259 | T7: 2 | U7: 15 | V7: 0 | W7: 1 | X7: 72 | Y7: 0 | Z7: 0 | AA7: 0 | AB7: 0 | AC7: 9 | AD7: 67 | AE7: 0 | AF7: 2775 | AG7: 0 | AH7: 0 | AI7: 2 | AJ7: 1 | AK7: 0 | AL7: 0 | AM7: 0 | AN7: 0 | AO7: 0 | AP7: 0 | AQ7: 0 | AR7: 205 | AS7: 7 | AT7: 39 | AU7: 957 | AV7: 991 | AW7: =SUM(E7:AV7) -> 14301
B8: Pittsburgh Lower North Side | D8: 2 | E8: 956 | F8: 1921 | G8: 506 | H8: 294 | I8: 1490 | J8: 22 | K8: 59 | L8: 634 | M8: 276 | N8: 83 | O8: 51 | P8: 1988 | Q8: 70 | R8: 334 | S8: 486 | T8: 2 | U8: 26 | V8: 0 | W8: 5 | X8: 71 | Y8: 0 | Z8: 0 | AA8: 0 | AB8: 0 | AC8: 10 | AD8: 70 | AE8: 0 | AF8: 1356 | AG8: 0 | AH8: 0 | AI8: 0 | AJ8: 0 | AK8: 0 | AL8: 0 | AM8: 0 | AN8: 0 | AO8: 0 | AP8: 0 | AQ8: 0 | AR8: 298 | AS8: 16 | AT8: 71 | AU8: 731 | AV8: 902 | AW8: =SUM(E8:AV8) -> 12728
B9: Pittsburgh Upper North Side | D9: 3 | E9: 2629 | F9: 3109 | G9: 2767 | H9: 2362 | I9: 8353 | J9: 61 | K9: 145 | L9: 1620 | M9: 671 | N9: 204 | O9: 127 | P9: 4449 | Q9: 166 | R9: 776 | S9: 1173 | T9: 9 | U9: 58 | V9: 0 | W9: 4 | X9: 177 | Y9: 0 | Z9: 0 | AA9: 0 | AB9: 0 | AC9: 20 | AD9: 173 | AE9: 0 | AF9: 5753 | AG9: 0 | AH9: 0 | AI9: 2 | AJ9: 3 | AK9: 2 | AL9: 0 | AM9: 0 | AN9: 0 | AO9: 0 | AP9: 0 | AQ9: 0 | AR9: 736 | AS9: 39 | AT9: 176 | AU9: 1886 | AV9: 2209 | AW9: =SUM(E9:AV9) -> 39859
B10: Allegheny County Northwest | D10: 4 | E10: 1573 | F10: 880 | G10: 780 | H10: 31613 | I10: 9518 | J10: 22 | K10: 59 | L10: 655 | M10: 245 | N10: 47 | O10: 51 | P10: 1556 | Q10: 37 | R10: 167 | S10: 249 | T10: 2 | U10: 7 | V10: 0 | W10: 0 | X10: 48 | Y10: 0 | Z10: 0 | AA10: 0 | AB10: 0 | AC10: 3 | AD10: 60 | AE10: 0 | AF10: 18423 | AG10: 0 | AH10: 0 | AI10: 405 | AJ10: 1398 | AK10: 702 | AL10: 0 | AM10: 0 | AN10: 0 | AO10: 0 | AP10: 0 | AQ10: 0 | AR10: 217 | AS10: 8 | AT10: 41 | AU10: 1202 | AV10: 1108 | AW10: =SUM(E10:AV10) -> 71076
B11: Allegheny County North (remainder) | D11: 5 | E11: 2667 | F11: 4222 | G11: 3100 | H11: 9360 | I11: 377743 | J11: 120 | K11: 609 | L11: 5574 | M11: 1194 | N11: 1139 | O11: 223 | P11: 7388 | Q11: 1466 | R11: 1471 | S11: 5816 | T11: 4 | U11: 3652 | V11: 456 | W11: 1173 | X11: 822 | Y11: 11 | Z11: 0 | AA11: 0 | AB11: 0 | AC11: 23 | AD11: 221 | AE11: 0 | AF11: 9756 | AG11: 13 | AH11: 103 | AI11: 58 | AJ11: 519 | AK11: 10622 | AL11: 0 | AM11: 0 | AN11: 0 | AO11: 0 | AP11: 0 | AQ11: 5103 | AR11: 1301 | AS11: 594 | AT11: 4922 | AU11: 2634 | AV11: 2997 | AW11: =SUM(E11:AV11) -> 467076
B12: Hazelwood | D12: 6 | E12: 153 | F12: 215 | G12: 84 | H12: 51 | I12: 439 | J12: 1059 | K12: 789 | L12: 3184 | M12: 1224 | N12: 310 | O12: 847 | P12: 1243 | Q12: 177 | R12: 128 | S12: 440 | T12: 82 | U12: 126 | V12: 3 | W12: 231 | X12: 581 | Y12: 31 | Z12: 54 | AA12: 17 | AB12: 2 | AC12: 187 | AD12: 645 | AE12: 42 | AF12: 486 | AG12: 0 | AH12: 0 | AI12: 0 | AJ12: 0 | AK12: 0 | AL12: 0 | AM12: 0 | AN12: 0 | AO12: 0 | AP12: 1 | AQ12: 3 | AR12: 395 | AS12: 30 | AT12: 180 | AU12: 609 | AV12: 550 | AW12: =SUM(E12:AV12) -> 14598
B13: Squirrel Hill | D13: 7 | E13: 543 | F13: 704 | G13: 256 | H13: 175 | I13: 2459 | J13: 983 | K13: 6910 | L13: 12701 | M13: 2553 | N13: 2865 | O13: 2561 | P13: 3590 | Q13: 1777 | R13: 443 | S13: 2980 | T13: 84 | U13: 879 | V13: 35 | W13: 1067 | X13: 4092 | Y13: 162 | Z13: 117 | AA13: 22 | AB13: 0 | AC13: 540 | AD13: 716 | AE13: 36 | AF13: 1927 | AG13: 0 | AH13: 0 | AI13: 0 | AJ13: 0 | AK13: 0 | AL13: 0 | AM13: 0 | AN13: 0 | AO13: 0 | AP13: 0 | AQ13: 41 | AR13: 1099 | AS13: 303 | AT13: 1851 | AU13: 1392 | AV13: 1451 | AW13: =SUM(E13:AV13) -> 57314
B14: Oakland | D14: 8 | E14: 345 | F14: 484 | G14: 198 | H14: 120 | I14: 1104 | J14: 291 | K14: 852 | L14: 10286 | M14: 1600 | N14: 770 | O14: 376 | P14: 2650 | Q14: 397 | R14: 343 | S14: 1693 | T14: 25 | U14: 156 | V14: 2 | W14: 221 | X14: 559 | Y14: 22 | Z14: 16 | AA14: 7 | AB14: 0 | AC14: 86 | AD14: 296 | AE14: 5 | AF14: 1109 | AG14: 0 | AH14: 0 | AI14: 0 | AJ14: 0 | AK14: 0 | AL14: 0 | AM14: 0 | AN14: 0 | AO14: 0 | AP14: 0 | AQ14: 0 | AR14: 1011 | AS14: 69 | AT14: 319 | AU14: 898 | AV14: 911 | AW14: =SUM(E14:AV14) -> 27221
B15: South Side | D15: 9 | E15: 375 | F15: 525 | G15: 194 | H15: 132 | I15: 894 | J15: 212 | K15: 331 | L15: 3321 | M15: 3324 | N15: 218 | O15: 284 | P15: 2725 | Q15: 98 | R15: 282 | S15: 557 | T15: 26 | U15: 65 | V15: 0 | W15: 130 | X15: 297 | Y15: 16 | Z15: 19 | AA15: 7 | AB15: 0 | AC15: 67 | AD15: 505 | AE15: 19 | AF15: 1273 | AG15: 0 | AH15: 0 | AI15: 0 | AJ15: 0 | AK15: 0 | AL15: 0 | AM15: 0 | AN15: 0 | AO15: 0 | AP15: 2 | AQ15: 0 | AR15: 882 | AS15: 18 | AT15: 106 | AU15: 2014 | AV15: 1404 | AW15: =SUM(E15:AV15) -> 20322
B16: Shadyside | D16: 10 | E16: 204 | F16: 425 | G16: 191 | H16: 67 | I16: 1850 | J16: 159 | K16: 1245 | L16: 6787 | M16: 597 | N16: 2790 | O16: 362 | P16: 1603 | Q16: 1388 | R16: 359 | S16: 2928 | T16: 12 | U16: 383 | V16: 11 | W16: 328 | X16: 1015 | Y16: 49 | Z16: 16 | AA16: 1 | AB16: 0 | AC16: 83 | AD16: 145 | AE16: 0 | AF16: 430 | AG16: 0 | AH16: 0 | AI16: 0 | AJ16: 0 | AK16: 0 | AL16: 0 | AM16: 0 | AN16: 0 | AO16: 0 | AP16: 0 | AQ16: 7 | AR16: 480 | AS16: 240 | AT16: 977 | AU16: 472 | AV16: 453 | AW16: =SUM(E16:AV16) -> 26057
B17: Waterfront (West Homestead Homestead Munhall(part)) | D17: 11 | E17: 82 | F17: 109 | G17: 40 | H17: 20 | I17: 158 | J17: 200 | K17: 455 | L17: 1074 | M17: 358 | N17: 160 | O17: 4433 | P17: 461 | Q17: 105 | R17: 48 | S17: 184 | T17: 76 | U17: 124 | V17: 2 | W17: 319 | X17: 1027 | Y17: 113 | Z17: 112 | AA17: 16 | AB17: 2 | AC17: 757 | AD17: 551 | AE17: 35 | AF17: 174 | AG17: 0 | AH17: 0 | AI17: 0 | AJ17: 0 | AK17: 0 | AL17: 0 | AM17: 0 | AN17: 0 | AO17: 0 | AP17: 0 | AQ17: 10 | AR17: 117 | AS17: 18 | AT17: 129 | AU17: 324 | AV17: 328 | AW17: =SUM(E17:AV17) -> 12121
B18: Downtown | D18: 12 | E18: 250 | F18: 439 | G18: 131 | H18: 90 | I18: 524 | J18: 27 | K18: 59 | L18: 660 | M18: 286 | N18: 65 | O18: 40 | P18: 1856 | Q18: 44 | R18: 206 | S18: 299 | T18: 3 | U18: 11 | V18: 0 | W18: 11 | X18: 59 | Y18: 1 | Z18: 0 | AA18: 0 | AB18: 0 | AC18: 8 | AD18: 71 | AE18: 1 | AF18: 710 | AG18: 0 | AH18: 0 | AI18: 0 | AJ18: 0 | AK18: 0 | AL18: 0 | AM18: 0 | AN18: 0 | AO18: 0 | AP18: 0 | AQ18: 0 | AR18: 344 | AS18: 10 | AT18: 36 | AU18: 476 | AV18: 566 | AW18: =SUM(E18:AV18) -> 7283
B19: East Liberty | D19: 13 | E19: 115 | F19: 218 | G19: 98 | H19: 31 | I19: 1564 | J19: 53 | K19: 476 | L19: 1887 | M19: 174 | N19: 800 | O19: 144 | P19: 624 | Q19: 1268 | R19: 182 | S19: 1445 | T19: 6 | U19: 291 | V19: 11 | W19: 198 | X19: 541 | Y19: 27 | Z19: 5 | AA19: 0 | AB19: 0 | AC19: 35 | AD19: 53 | AE19: 0 | AF19: 165 | AG19: 0 | AH19: 0 | AI19: 0 | AJ19: 0 | AK19: 0 | AL19: 0 | AM19: 0 | AN19: 0 | AO19: 0 | AP19: 0 | AQ19: 1 | AR19: 165 | AS19: 263 | AT19: 698 | AU19: 215 | AV19: 208 | AW19: =SUM(E19:AV19) -> 11961
... B50: Allegheny County Southcentral | D50: 44 | E50: 1571 | F50: 1828 | G50: 595 | H50: 576 | I50: 2057 | J50: 186 | K50: 317 | L50: 3150 | M50: 2087 | N50: 257 | O50: 647 | P50: 7326 | Q50: 172 | R50: 729 | S50: 1106 | T50: 82 | U50: 38 | V50: 0 | W50: 4 | X50: 288 | Y50: 2 | Z50: 45 | AA50: 28 | AB50: 8 | AC50: 226 | AD50: 9622 | AE50: 3310 | AF50: 45047 | AG50: 0 | AH50: 0 | AI50: 0 | AJ50: 0 | AK50: 0 | AL50: 0 | AM50: 0 | AN50: 0 | AO50: 0 | AP50: 15761 | AQ50: 0 | AR50: 1306 | AS50: 38 | AT50: 140 | AU50: 11434 | AV50: 144753 | AW50: =SUM(E50:AV50) -> 254736
D51: Total | E51: =SUM(E7:E50) -> 21282 | F51: =SUM(F7:F50) -> 26442 | G51: =SUM(G7:G50) -> 13705 | H51: =SUM(H7:H50) -> 63275 | I51: =SUM(I7:I50) -> 506816 | J51: =SUM(J7:J50) -> 7495 | K51: =SUM(K7:K50) -> 24591 | L51: =SUM(L7:L50) -> 103900 | ... AV51: =SUM(AV7:AV50) -> 244717 | AW51: =SUM(E51:AV51) -> 4706478
D60: - - - - - Table 2b - 2045 Home-Based Other (HBO) Person Trips - - - - -
B61: District Names | E61: Destination District
E62: 1 | F62: 2 | G62: 3 | H62: 4 | I62: 5 | J62: 6 | K62: 7 | L62: 8 | M62: 9 | N62: 10 | O62: 11 | P62: 12 | Q62: 13 | R62: 14 | S62: 15 | T62: 16 | U62: 17 | V62: 18 | W62: 19 | X62: 20 | Y62: 21 | Z62: 22 | AA62: 23 | AB62: 24 | AC62: 25 | AD62: 26 | AE62: 27 | AF62: 28 | AG62: 29 | AH62: 30 | AI62: 31 | AJ62: 32 | AK62: 33 | AL62: 34 | AM62: 35 | AN62: 36 | AO62: 37 | AP62: 38 | AQ62: 39 | AR62: 40 | AS62: 41 | AT62: 42 | AU62: 43 | AV62: 44 | AW62: Total
B63: Pittsburgh Chateau Area | C63: Origin District | D63: 1 | E63: 2303 | F63: 1332 | G63: 776 | H63: 1097 | I63: 1576 | J63: 65 | K63: 73 | L63: 688 | M63: 309 | N63: 49 | O63: 60 | P63: 2033 | Q63: 51 | R63: 280 | S63: 331 | T63: 1 | U63: 20 | V63: 0 | W63: 3 | X63: 84 | Y63: 0 | Z63: 0 | AA63: 0 | AB63: 0 | AC63: 13 | AD63: 96 | AE63: 0 | AF63: 2945 | AG63: 0 | AH63: 0 | AI63: 0 | AJ63: 0 | AK63: 0 | AL63: 0 | AM63: 0 | AN63: 0 | AO63: 0 | AP63: 0 | AQ63: 0 | AR63: 321 | AS63: 11 | AT63: 53 | AU63: 1219 | AV63: 1159 | AW63: =SUM(E63:AV63) -> 16948
B64: Pittsburgh Lower North Side | D64: 2 | E64: 1020 | F64: 2022 | G64: 586 | H64: 284 | I64: 1531 | J64: 67 | K64: 70 | L64: 688 | M64: 329 | N64: 85 | O64: 57 | P64: 2468 | Q64: 81 | R64: 486 | S64: 569 | T64: 3 | U64: 28 | V64: 0 | W64: 5 | X64: 83 | Y64: 0 | Z64: 0 | AA64: 0 | AB64: 0 | AC64: 13 | AD64: 69 | AE64: 0 | AF64: 1424 | AG64: 0 | AH64: 0 | AI64: 0 | AJ64: 0 | AK64: 0 | AL64: 0 | AM64: 0 | AN64: 0 | AO64: 0 | AP64: 0 | AQ64: 0 | AR64: 407 | AS64: 20 | AT64: 86 | AU64: 851 | AV64: 997 | AW64: =SUM(E64:AV64) -> 14329
B65: Pittsburgh Upper North Side | D65: 3 | E65: 2885 | F65: 3236 | G65: 3216 | H65: 2415 | I65: 8412 | J65: 174 | K65: 164 | L65: 1735 | M65: 784 | N65: 207 | O65: 146 | P65: 5419 | Q65: 193 | R65: 1122 | S65: 1361 | T65: 8 | U65: 63 | V65: 0 | W65: 3 | X65: 188 | Y65: 0 | Z65: 0 | AA65: 0 | AB65: 0 | AC65: 25 | AD65: 172 | AE65: 0 | AF65: 5698 | AG65: 0 | AH65: 0 | AI65: 0 | AJ65: 1 | AK65: 0 | AL65: 0 | AM65: 0 | AN65: 0 | AO65: 0 | AP65: 0 | AQ65: 0 | AR65: 955 | AS65: 45 | AT65: 209 | AU65: 2182 | AV65: 2414 | AW65: =SUM(E65:AV65) -> 43432
B66: Allegheny County Northwest | D66: 4 | E66: 1862 | F66: 980 | G66: 942 | H66: 35699 | I66: 8701 | J66: 69 | K66: 76 | L66: 779 | M66: 315 | N66: 51 | O66: 59 | P66: 2069 | Q66: 46 | R66: 261 | S66: 314 | T66: 3 | U66: 6 | V66: 0 | W66: 0 | X66: 57 | Y66: 0 | Z66: 0 | AA66: 0 | AB66: 0 | AC66: 4 | AD66: 71 | AE66: 0 | AF66: 20164 | AG66: 0 | AH66: 0 | AI66: 415 | AJ66: 1333 | AK66: 399 | AL66: 0 | AM66: 0 | AN66: 0 | AO66: 0 | AP66: 0 | AQ66: 0 | AR66: 322 | AS66: 11 | AT66: 50 | AU66: 1476 | AV66: 1241 | AW66: =SUM(E66:AV66) -> 77775
B67: Allegheny County North (remainder) | D67: 5 | E67: 2949 | F67: 4583 | G67: 3749 | H67: 11111 | I67: 448181 | J67: 349 | K67: 730 | L67: 6170 | M67: 1458 | N67: 1174 | O67: 241 | P67: 9570 | Q67: 1688 | R67: 2238 | S67: 6913 | T67: 8 | U67: 4073 | V67: 549 | W67: 970 | X67: 905 | Y67: 12 | Z67: 0 | AA67: 0 | AB67: 0 | AC67: 29 | AD67: 192 | AE67: 0 | AF67: 10980 | AG67: 14 | AH67: 137 | AI67: 89 | AJ67: 749 | AK67: 10730 | AL67: 0 | AM67: 0 | AN67: 0 | AO67: 0 | AP67: 0 | AQ67: 5301 | AR67: 1828 | AS67: 683 | AT67: 5744 | AU67: 3110 | AV67: 3394 | AW67: =SUM(E67:AV67) -> 550601
B68: Hazelwood | D68: 6 | E68: 215 | F68: 286 | G68: 114 | H68: 68 | I68: 575 | J68: 4252 | K68: 1145 | L68: 4890 | M68: 1984 | N68: 397 | O68: 1178 | P68: 1907 | Q68: 251 | R68: 229 | S68: 680 | T68: 117 | U68: 179 | V68: 3 | W68: 308 | X68: 849 | Y68: 49 | Z68: 73 | AA68: 21 | AB68: 3 | AC68: 257 | AD68: 894 | AE68: 65 | AF68: 540 | AG68: 0 | AH68: 0 | AI68: 0 | AJ68: 0 | AK68: 0 | AL68: 0 | AM68: 0 | AN68: 0 | AO68: 0 | AP68: 2 | AQ68: 2 | AR68: 770 | AS68: 43 | AT68: 270 | AU68: 942 | AV68: 730 | AW68: =SUM(E68:AV68) -> 24288
B69: Squirrel Hill | D69: 7 | E69: 560 | F69: 710 | G69: 287 | H69: 183 | I69: 2582 | J69: 2525 | K69: 8289 | L69: 14026 | M69: 2966 | N69: 2927 | O69: 2970 | P69: 4304 | Q69: 2089 | R69: 640 | S69: 3464 | T69: 89 | U69: 993 | V69: 36 | W69: 1110 | X69: 4881 | Y69: 196 | Z69: 113 | AA69: 21 | AB69: 0 | AC69: 633 | AD69: 715 | AE69: 35 | AF69: 1972 | AG69: 0 | AH69: 0 | AI69: 0 | AJ69: 0 | AK69: 0 | AL69: 0 | AM69: 0 | AN69: 0 | AO69: 0 | AP69: 0 | AQ69: 45 | AR69: 1540 | AS69: 361 | AT69: 2233 | AU69: 1599 | AV69: 1529 | AW69: =SUM(E69:AV69) -> 66623
B70: Oakland | D70: 8 | E70: 332 | F70: 445 | G70: 196 | H70: 111 | I70: 1040 | J70: 846 | K70: 943 | L70: 10962 | M70: 1786 | N70: 746 | O70: 409 | P70: 2899 | Q70: 437 | R70: 434 | S70: 1836 | T70: 21 | U70: 159 | V70: 1 | W70: 206 | X70: 602 | Y70: 27 | Z70: 11 | AA70: 5 | AB70: 0 | AC70: 88 | AD70: 286 | AE70: 7 | AF70: 1070 | AG70: 0 | AH70: 0 | AI70: 0 | AJ70: 0 | AK70: 0 | AL70: 0 | AM70: 0 | AN70: 0 | AO70: 0 | AP70: 0 | AQ70: 0 | AR70: 1396 | AS70: 81 | AT70: 356 | AU70: 968 | AV70: 892 | AW70: =SUM(E70:AV70) -> 29598
B71: South Side | D71: 9 | E71: 379 | F71: 515 | G71: 205 | H71: 125 | I71: 827 | J71: 633 | K71: 374 | L71: 3629 | M71: 3780 | N71: 214 | O71: 320 | P71: 3244 | Q71: 110 | R71: 389 | S71: 587 | T71: 32 | U71: 68 | V71: 0 | W71: 125 | X71: 326 | Y71: 16 | Z71: 21 | AA71: 8 | AB71: 0 | AC71: 78 | AD71: 521 | AE71: 21 | AF71: 1303 | AG71: 0 | AH71: 0 | AI71: 0 | AJ71: 0 | AK71: 0 | AL71: 0 | AM71: 0 | AN71: 0 | AO71: 0 | AP71: 1 | AQ71: 0 | AR71: 1244 | AS71: 18 | AT71: 115 | AU71: 2248 | AV71: 1419 | AW71: =SUM(E71:AV71) -> 22895
B72: Shadyside | D72: 10 | E72: 209 | F72: 427 | G72: 216 | H72: 67 | I72: 1890 | J72: 436 | K72: 1451 | L72: 7435 | M72: 685 | N72: 2806 | O72: 414 | P72: 1828 | Q72: 1610 | R72: 510 | S72: 3343 | T72: 14 | U72: 414 | V72: 12 | W72: 323 | X72: 1125 | Y72: 55 | Z72: 12 | AA72: 1 | AB72: 0 | AC72: 91 | AD72: 143 | AE72: 0 | AF72: 438 | AG72: 0 | AH72: 0 | AI72: 0 | AJ72: 0 | AK72: 0 | AL72: 0 | AM72: 0 | AN72: 0 | AO72: 0 | AP72: 0 | AQ72: 8 | AR72: 689 | AS72: 280 | AT72: 1148 | AU72: 515 | AV72: 450 | AW72: =SUM(E72:AV72) -> 29045
B73: Waterfront (West Homestead Homestead Munhall(part)) | D73: 11 | E73: 78 | F73: 97 | G73: 39 | H73: 18 | I73: 146 | J73: 451 | K73: 479 | L73: 1061 | M73: 374 | N73: 147 | O73: 4594 | P73: 498 | Q73: 109 | R73: 62 | S73: 185 | T73: 83 | U73: 110 | V73: 3 | W73: 305 | X73: 1044 | Y73: 112 | Z73: 96 | AA73: 17 | AB73: 2 | AC73: 788 | AD73: 594 | AE73: 46 | AF73: 161 | AG73: 0 | AH73: 0 | AI73: 0 | AJ73: 0 | AK73: 0 | AL73: 0 | AM73: 0 | AN73: 0 | AO73: 0 | AP73: 0 | AQ73: 9 | AR73: 148 | AS73: 20 | AT73: 131 | AU73: 335 | AV73: 313 | AW73: =SUM(E73:AV73) -> 12655
B74: Downtown | D74: 12 | E74: 380 | F74: 641 | G74: 222 | H74: 130 | I74: 797 | J74: 108 | K74: 99 | L74: 1077 | M74: 493 | N74: 101 | O74: 64 | P74: 3393 | Q74: 77 | R74: 440 | S74: 505 | T74: 8 | U74: 23 | V74: 0 | W74: 15 | X74: 95 | Y74: 0 | Z74: 0 | AA74: 0 | AB74: 0 | AC74: 16 | AD74: 113 | AE74: 1 | AF74: 1060 | AG74: 0 | AH74: 0 | AI74: 0 | AJ74: 0 | AK74: 0 | AL74: 0 | AM74: 0 | AN74: 0 | AO74: 0 | AP74: 0 | AQ74: 0 | AR74: 704 | AS74: 14 | AT74: 64 | AU74: 800 | AV74: 879 | AW74: =SUM(E74:AV74) -> 12319
B75: East Liberty | D75: 13 | E75: 118 | F75: 215 | G75: 111 | H75: 30 | I75: 1552 | J75: 136 | K75: 553 | L75: 2034 | M75: 193 | N75: 797 | O75: 162 | P75: 714 | Q75: 1453 | R75: 255 | S75: 1639 | T75: 4 | U75: 310 | V75: 15 | W75: 190 | X75: 601 | Y75: 32 | Z75: 3 | AA75: 0 | AB75: 0 | AC75: 45 | AD75: 38 | AE75: 0 | AF75: 175 | AG75: 0 | AH75: 0 | AI75: 0 | AJ75: 0 | AK75: 0 | AL75: 0 | AM75: 0 | AN75: 0 | AO75: 0 | AP75: 0 | AQ75: 1 | AR75: 221 | AS75: 303 | AT75: 809 | AU75: 232 | AV75: 202 | AW75: =SUM(E75:AV75) -> 13143
... B106: Allegheny County Southcentral | D106: 44 | E106: 1583 | F106: 1757 | G106: 647 | H106: 549 | I106: 1927 | J106: 450 | K106: 340 | L106: 3140 | M106: 2076 | N106: 219 | O106: 687 | P106: 7878 | Q106: 164 | R106: 904 | S106: 1054 | T106: 93 | U106: 36 | V106: 0 | W106: 2 | X106: 293 | Y106: 3 | Z106: 44 | AA106: 27 | AB106: 10 | AC106: 267 | AD106: 11202 | AE106: 3365 | AF106: 47638 | AG106: 0 | AH106: 0 | AI106: 1 | AJ106: 0 | AK106: 0 | AL106: 0 | AM106: 0 | AN106: 0 | AO106: 0 | AP106: 15074 | AQ106: 0 | AR106: 1486 | AS106: 35 | AT106: 136 | AU106: 12580 | AV106: 162034 | AW106: =SUM(E106:AV106) -> 277701
D107: Total | E107: =SUM(E63:E106) -> 23325 | F107: =SUM(F63:F106) -> 27489 | G107: =SUM(G63:G106) -> 15921 | H107: =SUM(H63:H106) -> 71227 | I107: =SUM(I63:I106) -> 583962 | J107: =SUM(J63:J106) -> 20557 | K107: =SUM(K63:K106) -> 28275 | L107: =SUM(L63:L106) -> 112376 | ... AV107: =SUM(AV63:AV106) -> 273768 | AW107: =SUM(E107:AV107) -> 5255198
D116: - - - - - Table 2c - Change - 2020 To 2045 - Home-Based Other (HBO) Person Trips - - - - -
B117: District Names | E117: Destination District
E118: 1 | F118: 2 | G118: 3 | H118: 4 | I118: 5 | J118: 6 | K118: 7 | L118: 8 | M118: 9 | N118: 10 | O118: 11 | P118: 12 | Q118: 13 | R118: 14 | S118: 15 | T118: 16 | U118: 17 | V118: 18 | W118: 19 | X118: 20 | Y118: 21 | Z118: 22 | AA118: 23 | AB118: 24 | AC118: 25 | AD118: 26 | AE118: 27 | AF118: 28 | AG118: 29 | AH118: 30 | AI118: 31 | AJ118: 32 | AK118: 33 | AL118: 34 | AM118: 35 | AN118: 36 | AO118: 37 | AP118: 38 | AQ118: 39 | AR118: 40 | AS118: 41 | AT118: 42 | AU118: 43 | AV118: 44 | AW118: Total
B119: Pittsburgh Chateau Area | C119: Origin District | D119: 1 | E119: =E63-E7 -> 411 | F119: =F63-F7 -> 166 | G119: =G63-G7 -> 140 | H119: =H63-H7 -> 66 | I119: =I63-I7 -> 76 | J119: =J63-J7 -> 47 | K119: =K63-K7 -> 13 | L119: =L63-L7 -> 125 | ... AV119: =AV63-AV7 -> 168 | AW119: =SUM(E119:AV119) -> 2647
...

Sheet T3_NHB_TotPers
D4: - - - - - Table 3a - 2020 Non Home-Based (NHB) Person Trips - - - - -
B5: District Names | E5: Destination District
E6: 1 | F6: 2 | G6: 3 | H6: 4 | I6: 5 | J6: 6 | K6: 7 | L6: 8 | M6: 9 | N6: 10 | O6: 11 | P6: 12 | Q6: 13 | R6: 14 | S6: 15 | T6: 16 | U6: 17 | V6: 18 | W6: 19 | X6: 20 | Y6: 21 | Z6: 22 | AA6: 23 | AB6: 24 | AC6: 25 | AD6: 26 | AE6: 27 | AF6: 28 | AG6: 29 | AH6: 30 | AI6: 31 | AJ6: 32 | AK6: 33 | AL6: 34 | AM6: 35 | AN6: 36 | AO6: 37 | AP6: 38 | AQ6: 39 | AR6: 40 | AS6: 41 | AT6: 42 | AU6: 43 | AV6: 44 | AW6: Total
B7: Pittsburgh Chateau Area | C7: Origin District | D7: 1 | E7: 841 | F7: 572 | G7: 292 | H7: 340 | I7: 727 | J7: 25 | K7: 82 | L7: 381 | M7: 213 | N7: 62 | O7: 64 | P7: 902 | Q7: 52 | R7: 112 | S7: 235 | T7: 5 | U7: 38 | V7: 7 | W7: 41 | X7: 98 | Y7: 12 | Z7: 14 | AA7: 4 | AB7: 4 | AC7: 25 | AD7: 114 | AE7: 13 | AF7: 729 | AG7: 0 | AH7: 0 | AI7: 10 | AJ7: 7 | AK7: 14 | AL7: 0 | AM7: 0 | AN7: 0 | AO7: 0 | AP7: 33 | AQ7: 18 | AR7: 117 | AS7: 14 | AT7: 54 | AU7: 693 | AV7: 534 | AW7: =SUM(E7:AV7) -> 7498
B8: Pittsburgh Lower North Side | D8: 2 | E8: 562 | F8: 999 | G8: 368 | H8: 233 | I8: 1142 | J8: 36 | K8: 105 | L8: 513 | M8: 304 | N8: 115 | O8: 82 | P8: 1443 | Q8: 95 | R8: 219 | S8: 460 | T8: 5 | U8: 57 | V8: 10 | W8: 54 | X8: 119 | Y8: 16 | Z8: 21 | AA8: 4 | AB8: 4 | AC8: 32 | AD8: 157 | AE8: 21 | AF8: 654 | AG8: 0 | AH8: 0 | AI8: 5 | AJ8: 10 | AK8: 20 | AL8: 0 | AM8: 0 | AN8: 0 | AO8: 0 | AP8: 43 | AQ8: 26 | AR8: 191 | AS8: 27 | AT8: 103 | AU8: 756 | AV8: 644 | AW8: =SUM(E8:AV8) -> 9655
B9: Pittsburgh Upper North Side | D9: 3 | E9: 303 | F9: 368 | G9: 390 | H9: 255 | I9: 1050 | J9: 17 | K9: 55 | L9: 274 | M9: 140 | N9: 71 | O9: 40 | P9: 655 | Q9: 56 | R9: 118 | S9: 271 | T9: 3 | U9: 35 | V9: 4 | W9: 27 | X9: 67 | Y9: 6 | Z9: 13 | AA9: 3 | AB9: 0 | AC9: 15 | AD9: 81 | AE9: 10 | AF9: 463 | AG9: 0 | AH9: 0 | AI9: 8 | AJ9: 4 | AK9: 19 | AL9: 0 | AM9: 0 | AN9: 0 | AO9: 0 | AP9: 19 | AQ9: 16 | AR9: 92 | AS9: 16 | AT9: 61 | AU9: 386 | AV9: 318 | AW9: =SUM(E9:AV9) -> 5729
B10: Allegheny County Northwest | D10: 4 | E10: 367 | F10: 219 | G10: 269 | H10: 8343 | I10: 2436 | J10: 17 | K10: 48 | L10: 244 | M10: 123 | N10: 39 | O10: 41 | P10: 477 | Q10: 31 | R10: 52 | S10: 125 | T10: 5 | U10: 23 | V10: 4 | W10: 26 | X10: 63 | Y10: 8 | Z10: 6 | AA10: 3 | AB10: 0 | AC10: 15 | AD10: 83 | AE10: 10 | AF10: 3158 | AG10: 0 | AH10: 0 | AI10: 419 | AJ10: 845 | AK10: 163 | AL10: 0 | AM10: 0 | AN10: 0 | AO10: 0 | AP10: 50 | AQ10: 4 | AR10: 60 | AS10: 7 | AT10: 34 | AU10: 473 | AV10: 382 | AW10: =SUM(E10:AV10) -> 18672
B11: Allegheny County North (remainder) | D11: 5 | E11: 798 | F11: 1198 | G11: 1079 | H11: 2451 | I11: 108076 | J11: 94 | K11: 462 | L11: 1911 | M11: 661 | N11: 641 | O11: 243 | P11: 2656 | Q11: 756 | R11: 459 | S11: 2119 | T11: 19 | U11: 2111 | V11: 418 | W11: 852 | X11: 738 | Y11: 109 | Z11: 81 | AA11: 15 | AB11: 1 | AC11: 128 | AD11: 453 | AE11: 45 | AF11: 2351 | AG11: 123 | AH11: 162 | AI11: 179 | AJ11: 710 | AK11: 3931 | AL11: 0 | AM11: 0 | AN11: 4 | AO11: 8 | AP11: 53 | AQ11: 3396 | AR11: 390 | AS11: 336 | AT11: 2092 | AU11: 1539 | AV11: 1409 | AW11: =SUM(E11:AV11) -> 145257
B12: Hazelwood | D12: 6 | E12: 25 | F12: 36 | G12: 16 | H12: 16 | I12: 99 | J12: 175 | K12: 177 | L12: 393 | M12: 204 | N12: 70 | O12: 180 | P12: 188 | Q12: 41 | R12: 19 | S12: 94 | T12: 24 | U12: 41 | V12: 7 | W12: 52 | X12: 136 | Y12: 16 | Z12: 34 | AA12: 13 | AB12: 4 | AC12: 71 | AD12: 191 | AE12: 24 | AF12: 61 | AG12: 0 | AH12: 0 | AI12: 0 | AJ12: 0 | AK12: 0 | AL12: 0 | AM12: 0 | AN12: 0 | AO12: 0 | AP12: 9 | AQ12: 17 | AR12: 45 | AS12: 10 | AT12: 46 | AU12: 143 | AV12: 104 | AW12: =SUM(E12:AV12) -> 2781
B13: Squirrel Hill | D13: 7 | E13: 75 | F13: 99 | G13: 48 | H13: 47 | I13: 483 | J13: 177 | K13: 1502 | L13: 1523 | M13: 432 | N13: 593 | O13: 500 | P13: 527 | Q13: 379 | R13: 68 | S13: 563 | T13: 33 | U13: 254 | V13: 23 | W13: 213 | X13: 810 | Y13: 64 | Z13: 65 | AA13: 17 | AB13: 10 | AC13: 177 | AD13: 232 | AE13: 23 | AF13: 197 | AG13: 0 | AH13: 1 | AI13: 0 | AJ13: 0 | AK13: 2 | AL13: 0 | AM13: 0 | AN13: 0 | AO13: 0 | AP13: 18 | AQ13: 72 | AR13: 124 | AS13: 84 | AT13: 450 | AU13: 321 | AV13: 245 | AW13: =SUM(E13:AV13) -> 10451
B14: Oakland | D14: 8 | E14: 388 | F14: 533 | G14: 306 | H14: 252 | I14: 1963 | J14: 408 | K14: 1510 | L14: 10276 | M14: 1902 | N14: 1394 | O14: 673 | P14: 2935 | Q14: 778 | R14: 401 | S14: 2557 | T14: 73 | U14: 443 | V14: 60 | W14: 391 | X14: 1110 | Y14: 101 | Z14: 125 | AA14: 48 | AB14: 29 | AC14: 273 | AD14: 763 | AE14: 94 | AF14: 1002 | AG14: 0 | AH14: 0 | AI14: 2 | AJ14: 3 | AK14: 10 | AL14: 0 | AM14: 0 | AN14: 0 | AO14: 0 | AP14: 76 | AQ14: 143 | AR14: 831 | AS14: 178 | AT14: 720 | AU14: 1565 | AV14: 1197 | AW14: =SUM(E14:AV14) -> 35513
B15: South Side | D15: 9 | E15: 214 | F15: 296 | G15: 149 | H15: 119 | I15: 751 | J15: 198 | K15: 410 | L15: 1905 | M15: 2251 | N15: 252 | O15: 320 | P15: 1599 | Q15: 126 | R15: 172 | S15: 483 | T15: 47 | U15: 125 | V15: 20 | W15: 150 | X15: 383 | Y15: 37 | Z15: 59 | AA15: 25 | AB15: 15 | AC15: 137 | AD15: 555 | AE15: 49 | AF15: 544 | AG15: 0 | AH15: 0 | AI15: 3 | AJ15: 4 | AK15: 10 | AL15: 0 | AM15: 0 | AN15: 0 | AO15: 0 | AP15: 56 | AQ15: 48 | AR15: 417 | AS15: 29 | AT15: 153 | AU15: 1454 | AV15: 855 | AW15: =SUM(E15:AV15) -> 14420
B16: Shadyside | D16: 10 | E16: 59 | F16: 118 | G16: 72 | H16: 40 | I16: 642 | J16: 68 | K16: 579 | L16: 1537 | M16: 224 | N16: 1104 | O16: 181 | P16: 463 | Q16: 528 | R16: 101 | S16: 1000 | T16: 11 | U16: 236 | V16: 18 | W16: 154 | X16: 472 | Y16: 45 | Z16: 29 | AA16: 6 | AB16: 5 | AC16: 72 | AD16: 111 | AE16: 15 | AF16: 133 | AG16: 0 | AH16: 0 | AI16: 0 | AJ16: 0 | AK16: 3 | AL16: 0 | AM16: 0 | AN16: 0 | AO16: 0 | AP16: 10 | AQ16: 56 | AR16: 111 | AS16: 120 | AT16: 444 | AU16: 229 | AV16: 173 | AW16: =SUM(E16:AV16) -> 9169
B17: Waterfront (West Homestead Homestead Munhall(part)) | D17: 11 | E17: 59 | F17: 76 | G17: 40 | H17: 38 | I17: 254 | J17: 189 | K17: 496 | L17: 697 | M17: 347 | N17: 185 | O17: 3432 | P17: 360 | Q17: 123 | R17: 39 | S17: 194 | T17: 116 | U17: 153 | V17: 22 | W17: 253 | X17: 834 | Y17: 162 | Z17: 227 | AA17: 58 | AB17: 23 | AC17: 891 | AD17: 786 | AE17: 93 | AF17: 169 | AG17: 0 | AH17: 0 | AI17: 0 | AJ17: 0 | AK17: 0 | AL17: 0 | AM17: 0 | AN17: 0 | AO17: 0 | AP17: 36 | AQ17: 104 | AR17: 75 | AS17: 28 | AT17: 153 | AU17: 416 | AV17: 345 | AW17: =SUM(E17:AV17) -> 11473
B18: Downtown | D18: 12 | E18: 878 | F18: 1479 | G18: 662 | H18: 469 | I18: 2645 | J18: 195 | K18: 539 | L18: 2794 | M18: 1681 | N18: 501 | O18: 366 | P18: 7501 | Q18: 342 | R18: 842 | S18: 1622 | T18: 43 | U18: 215 | V18: 40 | W18: 234 | X18: 565 | Y18: 53 | Z18: 87 | AA18: 27 | AB18: 18 | AC18: 147 | AD18: 801 | AE18: 87 | AF18: 1847 | AG18: 0 | AH18: 0 | AI18: 10 | AJ18: 16 | AK18: 42 | AL18: 0 | AM18: 0 | AN18: 0 | AO18: 0 | AP18: 165 | AQ18: 94 | AR18: 1106 | AS18: 94 | AT18: 323 | AU18: 3037 | AV18: 2398 | AW18: =SUM(E18:AV18) -> 33965
B19: East Liberty | D19: 13 | E19: 52 | F19: 98 | G19: 58 | H19: 36 | I19: 750 | J19: 41 | K19: 373 | L19: 800 | M19: 122 | N19: 531 | O19: 121 | P19: 319 | Q19: 765 | R19: 82 | S19: 803 | T19: 9 | U19: 288 | V19: 24 | W19: 142 | X19: 427 | Y19: 43 | Z19: 26 | AA19: 6 | AB19: 2 | AC19: 57 | AD19: 72 | AE19: 11 | AF19: 111 | AG19: 0 | AH19: 0 | AI19: 0 | AJ19: 0 | AK19: 5 | AL19: 0 | AM19: 0 | AN19: 0 | AO19: 0 | AP19: 6 | AQ19: 59 | AR19: 64 | AS19: 178 | AT19: 520 | AU19: 171 | AV19: 138 | AW19: =SUM(E19:AV19) -> 7310
... B50: Allegheny County Southcentral | D50: 44 | E50: 516 | F50: 620 | G50: 311 | H50: 349 | I50: 1384 | J50: 99 | K50: 258 | L50: 1249 | M50: 878 | N50: 198 | O50: 355 | P50: 2496 | Q50: 138 | R50: 268 | S50: 575 | T50: 56 | U50: 123 | V50: 19 | W50: 168 | X50: 339 | Y50: 67 | Z50: 150 | AA50: 59 | AB50: 53 | AC50: 224 | AD50: 3910 | AE50: 1305 | AF50: 7641 | AG50: 0 | AH50: 0 | AI50: 36 | AJ50: 18 | AK50: 11 | AL50: 1 | AM50: 0 | AN50: 0 | AO50: 0 | AP50: 3288 | AQ50: 60 | AR50: 368 | AS50: 36 | AT50: 157 | AU50: 4958 | AV50: 36674 | AW50: =SUM(E50:AV50) -> 69415
D51: Total | E51: =SUM(E7:E50) -> 7531 | F51: =SUM(F7:F50) -> 9711 | G51: =SUM(G7:G50) -> 5777 | H51: =SUM(H7:H50) -> 18807 | I51: =SUM(I7:I50) -> 145930 | J51: =SUM(J7:J50) -> 2800 | K51: =SUM(K7:K50) -> 10523 | L51: =SUM(L7:L50) -> 35734 | ... AV51: =SUM(AV7:AV50) -> 69731 | AW51: =SUM(E51:AV51) -> 1371044
D60: - - - - - Table 3b - 2045 Non Home-Based (NHB) Person Trips - - - - -
B61: District Names | E61: Destination District
E62: 1 | F62: 2 | G62: 3 | H62: 4 | I62: 5 | J62: 6 | K62: 7 | L62: 8 | M62: 9 | N62: 10 | O62: 11 | P62: 12 | Q62: 13 | R62: 14 | S62: 15 | T62: 16 | U62: 17 | V62: 18 | W62: 19 | X62: 20 | Y62: 21 | Z62: 22 | AA62: 23 | AB62: 24 | AC62: 25 | AD62: 26 | AE62: 27 | AF62: 28 | AG62: 29 | AH62: 30 | AI62: 31 | AJ62: 32 | AK62: 33 | AL62: 34 | AM62: 35 | AN62: 36 | AO62: 37 | AP62: 38 | AQ62: 39 | AR62: 40 | AS62: 41 | AT62: 42 | AU62: 43 | AV62: 44 | AW62: Total
B63: Pittsburgh Chateau Area | C63: Origin District | D63: 1 | E63: 920 | F63: 572 | G63: 326 | H63: 360 | I63: 788 | J63: 58 | K63: 86 | L63: 398 | M63: 226 | N63: 57 | O63: 64 | P63: 1043 | Q63: 57 | R63: 157 | S63: 262 | T63: 5 | U63: 40 | V63: 6 | W63: 42 | X63: 96 | Y63: 12 | Z63: 14 | AA63: 5 | AB63: 3 | AC63: 27 | AD63: 122 | AE63: 16 | AF63: 781 | AG63: 0 | AH63: 0 | AI63: 7 | AJ63: 8 | AK63: 13 | AL63: 0 | AM63: 0 | AN63: 0 | AO63: 0 | AP63: 36 | AQ63: 19 | AR63: 152 | AS63: 15 | AT63: 68 | AU63: 769 | AV63: 561 | AW63: =SUM(E63:AV63) -> 8191
B64: Pittsburgh Lower North Side | D64: 2 | E64: 565 | F64: 951 | G64: 382 | H64: 233 | I64: 1157 | J64: 76 | K64: 107 | L64: 485 | M64: 309 | N64: 106 | O64: 78 | P64: 1561 | Q64: 98 | R64: 287 | S64: 481 | T64: 9 | U64: 50 | V64: 15 | W64: 48 | X64: 120 | Y64: 12 | Z64: 19 | AA64: 6 | AB64: 1 | AC64: 34 | AD64: 140 | AE64: 19 | AF64: 659 | AG64: 0 | AH64: 0 | AI64: 4 | AJ64: 9 | AK64: 18 | AL64: 0 | AM64: 0 | AN64: 0 | AO64: 0 | AP64: 46 | AQ64: 28 | AR64: 234 | AS64: 29 | AT64: 105 | AU64: 774 | AV64: 637 | AW64: =SUM(E64:AV64) -> 9892
B65: Pittsburgh Upper North Side | D65: 3 | E65: 343 | F65: 385 | G65: 456 | H65: 288 | I65: 1177 | J65: 44 | K65: 55 | L65: 297 | M65: 157 | N65: 73 | O65: 43 | P65: 764 | Q65: 66 | R65: 176 | S65: 305 | T65: 3 | U65: 38 | V65: 4 | W65: 28 | X65: 70 | Y65: 8 | Z65: 11 | AA65: 4 | AB65: 0 | AC65: 22 | AD65: 77 | AE65: 15 | AF65: 501 | AG65: 0 | AH65: 0 | AI65: 3 | AJ65: 10 | AK65: 17 | AL65: 0 | AM65: 0 | AN65: 0 | AO65: 0 | AP65: 25 | AQ65: 16 | AR65: 121 | AS65: 18 | AT65: 71 | AU65: 430 | AV65: 344 | AW65: =SUM(E65:AV65) -> 6465
B66: Allegheny County Northwest | D66: 4 | E66: 403 | F66: 219 | G66: 295 | H66: 9081 | I66: 2575 | J66: 34 | K66: 52 | L66: 249 | M66: 126 | N66: 35 | O66: 39 | P66: 542 | Q66: 33 | R66: 78 | S66: 141 | T66: 4 | U66: 23 | V66: 4 | W66: 29 | X66: 59 | Y66: 8 | Z66: 6 | AA66: 3 | AB66: 0 | AC66: 20 | AD66: 85 | AE66: 13 | AF66: 3409 | AG66: 0 | AH66: 0 | AI66: 420 | AJ66: 879 | AK66: 182 | AL66: 0 | AM66: 0 | AN66: 0 | AO66: 0 | AP66: 47 | AQ66: 4 | AR66: 83 | AS66: 7 | AT66: 41 | AU66: 519 | AV66: 392 | AW66: =SUM(E66:AV66) -> 20139
B67: Allegheny County North (remainder) | D67: 5 | E67: 863 | F67: 1224 | G67: 1210 | H67: 2584 | I67: 121400 | J67: 229 | K67: 504 | L67: 1950 | M67: 708 | N67: 621 | O67: 249 | P67: 3097 | Q67: 817 | R67: 647 | S67: 2335 | T67: 22 | U67: 2192 | V67: 494 | W67: 818 | X67: 773 | Y67: 113 | Z67: 82 | AA67: 19 | AB67: 1 | AC67: 134 | AD67: 443 | AE67: 52 | AF67: 2472 | AG67: 113 | AH67: 169 | AI67: 171 | AJ67: 798 | AK67: 4576 | AL67: 0 | AM67: 0 | AN67: 2 | AO67: 8 | AP67: 53 | AQ67: 3500 | AR67: 529 | AS67: 362 | AT67: 2306 | AU67: 1643 | AV67: 1483 | AW67: =SUM(E67:AV67) -> 161766
B68: Hazelwood | D68: 6 | E68: 58 | F68: 70 | G68: 43 | H68: 37 | I68: 239 | J68: 1024 | K68: 393 | L68: 972 | M68: 522 | N68: 147 | O68: 368 | P68: 470 | Q68: 95 | R68: 62 | S68: 222 | T68: 54 | U68: 98 | V68: 14 | W68: 119 | X68: 310 | Y68: 33 | Z68: 70 | AA68: 29 | AB68: 12 | AC68: 142 | AD68: 396 | AE68: 52 | AF68: 152 | AG68: 0 | AH68: 0 | AI68: 0 | AJ68: 0 | AK68: 0 | AL68: 0 | AM68: 0 | AN68: 0 | AO68: 0 | AP68: 20 | AQ68: 38 | AR68: 154 | AS68: 21 | AT68: 116 | AU68: 361 | AV68: 223 | AW68: =SUM(E68:AV68) -> 7136
B69: Squirrel Hill | D69: 7 | E69: 79 | F69: 104 | G69: 59 | H69: 49 | I69: 530 | J69: 395 | K69: 1760 | L69: 1646 | M69: 478 | N69: 602 | O69: 544 | P69: 621 | Q69: 439 | R69: 93 | S69: 651 | T69: 25 | U69: 285 | V69: 25 | W69: 233 | X69: 887 | Y69: 73 | Z69: 60 | AA69: 15 | AB69: 8 | AC69: 190 | AD69: 222 | AE69: 28 | AF69: 222 | AG69: 0 | AH69: 0 | AI69: 0 | AJ69: 0 | AK69: 3 | AL69: 0 | AM69: 0 | AN69: 0 | AO69: 0 | AP69: 22 | AQ69: 80 | AR69: 182 | AS69: 99 | AT69: 526 | AU69: 361 | AV69: 259 | AW69: =SUM(E69:AV69) -> 11855
B70: Oakland | D70: 8 | E70: 386 | F70: 509 | G70: 321 | H70: 255 | I70: 1986 | J70: 999 | K70: 1626 | L70: 10642 | M70: 2034 | N70: 1328 | O70: 675 | P70: 3167 | Q70: 833 | R70: 525 | S70: 2719 | T70: 71 | U70: 452 | V70: 71 | W70: 397 | X70: 1139 | Y70: 104 | Z70: 119 | AA70: 41 | AB70: 25 | AC70: 265 | AD70: 685 | AE70: 97 | AF70: 1055 | AG70: 0 | AH70: 0 | AI70: 1 | AJ70: 1 | AK70: 7 | AL70: 0 | AM70: 0 | AN70: 0 | AO70: 0 | AP70: 80 | AQ70: 153 | AR70: 1166 | AS70: 194 | AT70: 783 | AU70: 1651 | AV70: 1204 | AW70: =SUM(E70:AV70) -> 37766
B71: South Side | D71: 9 | E71: 230 | F71: 301 | G71: 171 | H71: 133 | I71: 790 | J71: 506 | K71: 458 | L71: 2053 | M71: 2498 | N71: 251 | O71: 342 | P71: 1893 | Q71: 141 | R71: 244 | S71: 530 | T71: 53 | U71: 132 | V71: 22 | W71: 162 | X71: 408 | Y71: 38 | Z71: 62 | AA71: 26 | AB71: 17 | AC71: 141 | AD71: 565 | AE71: 51 | AF71: 598 | AG71: 0 | AH71: 0 | AI71: 3 | AJ71: 2 | AK71: 10 | AL71: 0 | AM71: 0 | AN71: 0 | AO71: 0 | AP71: 60 | AQ71: 55 | AR71: 595 | AS71: 32 | AT71: 168 | AU71: 1609 | AV71: 858 | AW71: =SUM(E71:AV71) -> 16208
B72: Shadyside | D72: 10 | E72: 58 | F72: 110 | G72: 71 | H72: 36 | I72: 615 | J72: 143 | K72: 590 | L72: 1474 | M72: 223 | N72: 984 | O72: 172 | P72: 475 | Q72: 537 | R72: 127 | S72: 1018 | T72: 9 | U72: 228 | V72: 22 | W72: 141 | X72: 447 | Y72: 44 | Z72: 26 | AA72: 7 | AB72: 3 | AC72: 62 | AD72: 94 | AE72: 15 | AF72: 132 | AG72: 0 | AH72: 0 | AI72: 0 | AJ72: 0 | AK72: 5 | AL72: 0 | AM72: 0 | AN72: 0 | AO72: 0 | AP72: 9 | AQ72: 54 | AR72: 140 | AS72: 123 | AT72: 454 | AU72: 221 | AV72: 159 | AW72: =SUM(E72:AV72) -> 9028
B73: Waterfront (West Homestead Homestead Munhall(part)) | D73: 11 | E73: 62 | F73: 71 | G73: 42 | H73: 35 | I73: 261 | J73: 383 | K73: 542 | L73: 697 | M73: 364 | N73: 176 | O73: 3450 | P73: 402 | Q73: 131 | R73: 55 | S73: 208 | T73: 126 | U73: 150 | V73: 21 | W73: 269 | X73: 826 | Y73: 163 | Z73: 199 | AA73: 58 | AB73: 24 | AC73: 872 | AD73: 820 | AE73: 112 | AF73: 179 | AG73: 0 | AH73: 0 | AI73: 0 | AJ73: 0 | AK73: 0 | AL73: 0 | AM73: 0 | AN73: 0 | AO73: 0 | AP73: 43 | AQ73: 111 | AR73: 100 | AS73: 30 | AT73: 164 | AU73: 445 | AV73: 342 | AW73: =SUM(E73:AV73) -> 11933
B74: Downtown | D74: 12 | E74: 1012 | F74: 1590 | G74: 775 | H74: 532 | I74: 3051 | J74: 487 | K74: 624 | L74: 3019 | M74: 1970 | N74: 523 | O74: 404 | P74: 9326 | Q74: 397 | R74: 1261 | S74: 1869 | T74: 51 | U74: 236 | V74: 48 | W74: 253 | X74: 619 | Y74: 66 | Z74: 94 | AA74: 27 | AB74: 20 | AC74: 162 | AD74: 819 | AE74: 101 | AF74: 2144 | AG74: 0 | AH74: 0 | AI74: 9 | AJ74: 15 | AK74: 46 | AL74: 0 | AM74: 0 | AN74: 0 | AO74: 0 | AP74: 189 | AQ74: 112 | AR74: 1572 | AS74: 114 | AT74: 379 | AU74: 3481 | AV74: 2644 | AW74: =SUM(E74:AV74) -> 40041
B75: East Liberty | D75: 13 | E75: 56 | F75: 101 | G75: 69 | H75: 35 | I75: 806 | J75: 94 | K75: 428 | L75: 862 | M75: 132 | N75: 541 | O75: 130 | P75: 365 | Q75: 883 | R75: 117 | S75: 923 | T75: 11 | U75: 312 | V75: 27 | W75: 153 | X75: 463 | Y75: 45 | Z75: 26 | AA75: 6 | AB75: 4 | AC75: 55 | AD75: 66 | AE75: 13 | AF75: 129 | AG75: 0 | AH75: 0 | AI75: 0 | AJ75: 0 | AK75: 5 | AL75: 0 | AM75: 0 | AN75: 0 | AO75: 0 | AP75: 7 | AQ75: 64 | AR75: 96 | AS75: 207 | AT75: 601 | AU75: 188 | AV75: 139 | AW75: =SUM(E75:AV75) -> 8159
... B106: Allegheny County Southcentral | D106: 44 | E106: 552 | F106: 615 | G106: 322 | H106: 379 | I106: 1437 | J106: 227 | K106: 281 | L106: 1248 | M106: 879 | N106: 179 | O106: 363 | P106: 2703 | Q106: 135 | R106: 348 | S106: 576 | T106: 64 | U106: 129 | V106: 19 | W106: 192 | X106: 339 | Y106: 69 | Z106: 158 | AA106: 57 | AB106: 56 | AC106: 216 | AD106: 4333 | AE106: 1380 | AF106: 8468 | AG106: 0 | AH106: 0 | AI106: 37 | AJ106: 17 | AK106: 13 | AL106: 2 | AM106: 0 | AN106: 0 | AO106: 0 | AP106: 3677 | AQ106: 51 | AR106: 449 | AS106: 43 | AT106: 164 | AU106: 5438 | AV106: 40440 | AW106: =SUM(E106:AV106) -> 76055
D107: Total | E107: =SUM(E63:E106) -> 8255 | F107: =SUM(F63:F106) -> 9942 | G107: =SUM(G63:G106) -> 6500 | H107: =SUM(H63:H106) -> 20240 | I107: =SUM(I63:I106) -> 162563 | J107: =SUM(J63:J106) -> 7182 | K107: =SUM(K63:K106) -> 11909 | L107: =SUM(L63:L106) -> 38034 | ... AV107: =SUM(AV63:AV106) -> 76496 | AW107: =SUM(E107:AV107) -> 1494658
D116: - - - - - Table 3c - Change - 2020 To 2045 - Non Home-Based (NHB) Person Trips - - - - -
B117: District Names | E117: Destination District
E118: 1 | F118: 2 | G118: 3 | H118: 4 | I118: 5 | J118: 6 | K118: 7 | L118: 8 | M118: 9 | N118: 10 | O118: 11 | P118: 12 | Q118: 13 | R118: 14 | S118: 15 | T118: 16 | U118: 17 | V118: 18 | W118: 19 | X118: 20 | Y118: 21 | Z118: 22 | AA118: 23 | AB118: 24 | AC118: 25 | AD118: 26 | AE118: 27 | AF118: 28 | AG118: 29 | AH118: 30 | AI118: 31 | AJ118: 32 | AK118: 33 | AL118: 34 | AM118: 35 | AN118: 36 | AO118: 37 | AP118: 38 | AQ118: 39 | AR118: 40 | AS118: 41 | AT118: 42 | AU118: 43 | AV118: 44 | AW118: Total
B119: Pittsburgh Chateau Area | C119: Origin District | D119: 1 | E119: =E63-E7 -> 79 | F119: =F63-F7 -> 0 | G119: =G63-G7 -> 34 | H119: =H63-H7 -> 20 | I119: =I63-I7 -> 61 | J119: =J63-J7 -> 33 | K119: =K63-K7 -> 4 | L119: =L63-L7 -> 17 | ... AV119: =AV63-AV7 -> 27 | AW119: =SUM(E119:AV119) -> 693
...

Sheet T4_HBW_HwyVeh
D4: - - - - - Table 4a - 2020 Home-Based Work (HBW) Vehicle Trips - - - - -
B5: District Names | E5: Destination District
E6: 1 | F6: 2 | G6: 3 | H6: 4 | I6: 5 | J6: 6 | K6: 7 | L6: 8 | M6: 9 | N6: 10 | O6: 11 | P6: 12 | Q6: 13 | R6: 14 | S6: 15 | T6: 16 | U6: 17 | V6: 18 | W6: 19 | X6: 20 | Y6: 21 | Z6: 22 | AA6: 23 | AB6: 24 | AC6: 25 | AD6: 26 | AE6: 27 | AF6: 28 | AG6: 29 | AH6: 30 | AI6: 31 | AJ6: 32 | AK6: 33 | AL6: 34 | AM6: 35 | AN6: 36 | AO6: 37 | AP6: 38 | AQ6: 39 | AR6: 40 | AS6: 41 | AT6: 42 | AU6: 43 | AV6: 44 | AW6: Total
B7: Pittsburgh Chateau Area | C7: Origin District | D7: 1 | E7: 532 | F7: 380 | G7: 174 | H7: 103 | I7: 202 | J7: 8 | K7: 14 | L7: 202 | M7: 76 | N7: 13 | O7: 3 | P7: 597 | Q7: 12 | R7: 44 | S7: 94 | T7: 0 | U7: 5 | V7: 0 | W7: 5 | X7: 10 | Y7: 2 | Z7: 0 | AA7: 0 | AB7: 0 | AC7: 3 | AD7: 11 | AE7: 0 | AF7: 304 | AG7: 0 | AH7: 0 | AI7: 1 | AJ7: 2 | AK7: 2 | AL7: 0 | AM7: 0 | AN7: 0 | AO7: 0 | AP7: 4 | AQ7: 0 | AR7: 84 | AS7: 3 | AT7: 11 | AU7: 224 | AV7: 144 | AW7: =SUM(E7:AV7) -> 3269
B8: Pittsburgh Lower North Side | D8: 2 | E8: 224 | F8: 427 | G8: 105 | H8: 23 | I8: 116 | J8: 6 | K8: 12 | L8: 139 | M8: 58 | N8: 13 | O8: 2 | P8: 548 | Q8: 13 | R8: 35 | S8: 88 | T8: 0 | U8: 4 | V8: 0 | W8: 5 | X8: 7 | Y8: 0 | Z8: 0 | AA8: 0 | AB8: 0 | AC8: 0 | AD8: 4 | AE8: 0 | AF8: 90 | AG8: 0 | AH8: 0 | AI8: 0 | AJ8: 0 | AK8: 3 | AL8: 0 | AM8: 0 | AN8: 0 | AO8: 0 | AP8: 1 | AQ8: 1 | AR8: 74 | AS8: 2 | AT8: 10 | AU8: 111 | AV8: 72 | AW8: =SUM(E8:AV8) -> 2193
B9: Pittsburgh Upper North Side | D9: 3 | E9: 908 | F9: 1032 | G9: 712 | H9: 320 | I9: 1015 | J9: 25 | K9: 53 | L9: 750 | M9: 219 | N9: 61 | O9: 9 | P9: 2261 | Q9: 54 | R9: 195 | S9: 401 | T9: 3 | U9: 15 | V9: 1 | W9: 11 | X9: 35 | Y9: 4 | Z9: 0 | AA9: 0 | AB9: 0 | AC9: 3 | AD9: 21 | AE9: 2 | AF9: 742 | AG9: 0 | AH9: 0 | AI9: 1 | AJ9: 4 | AK9: 13 | AL9: 0 | AM9: 0 | AN9: 0 | AO9: 0 | AP9: 9 | AQ9: 1 | AR9: 299 | AS9: 8 | AT9: 40 | AU9: 490 | AV9: 288 | AW9: =SUM(E9:AV9) -> 10005
B10: Allegheny County Northwest | D10: 4 | E10: 944 | F10: 710 | G10: 459 | H10: 7278 | I10: 2766 | J10: 27 | K10: 47 | L10: 701 | M10: 222 | N10: 45 | O10: 11 | P10: 1507 | Q10: 42 | R10: 121 | S10: 269 | T10: 3 | U10: 10 | V10: 0 | W10: 9 | X10: 35 | Y10: 2 | Z10: 0 | AA10: 0 | AB10: 0 | AC10: 2 | AD10: 18 | AE10: 1 | AF10: 4947 | AG10: 0 | AH10: 0 | AI10: 134 | AJ10: 373 | AK10: 147 | AL10: 0 | AM10: 0 | AN10: 0 | AO10: 0 | AP10: 66 | AQ10: 0 | AR10: 229 | AS10: 4 | AT10: 30 | AU10: 710 | AV10: 512 | AW10: =SUM(E10:AV10) -> 22381
B11: Allegheny County North (remainder) | D11: 5 | E11: 2838 | F11: 4158 | G11: 2476 | H11: 3654 | I11: 105936 | J11: 172 | K11: 730 | L11: 7696 | M11: 1110 | N11: 1025 | O11: 111 | P11: 13722 | Q11: 1583 | R11: 1230 | S11: 5350 | T11: 10 | U11: 1696 | V11: 278 | W11: 898 | X11: 615 | Y11: 54 | Z11: 6 | AA11: 0 | AB11: 0 | AC11: 22 | AD11: 58 | AE11: 0 | AF11: 4325 | AG11: 29 | AH11: 55 | AI11: 74 | AJ11: 283 | AK11: 3413 | AL11: 0 | AM11: 0 | AN11: 2 | AO11: 1 | AP11: 17 | AQ11: 1530 | AR11: 1629 | AS11: 389 | AT11: 2333 | AU11: 2003 | AV11: 1237 | AW11: =SUM(E11:AV11) -> 172748
B12: Hazelwood | D12: 6 | E12: 69 | F12: 97 | G12: 32 | H12: 13 | I12: 75 | J12: 324 | K12: 202 | L12: 743 | M12: 287 | N12: 81 | O12: 86 | P12: 500 | Q12: 61 | R12: 35 | S12: 138 | T12: 19 | U12: 15 | V12: 1 | W12: 20 | X12: 79 | Y12: 5 | Z12: 5 | AA12: 2 | AB12: 0 | AC12: 23 | AD12: 64 | AE12: 6 | AF12: 58 | AG12: 0 | AH12: 0 | AI12: 0 | AJ12: 0 | AK12: 0 | AL12: 0 | AM12: 0 | AN12: 0 | AO12: 0 | AP12: 1 | AQ12: 1 | AR12: 130 | AS12: 8 | AT12: 55 | AU12: 139 | AV12: 65 | AW12: =SUM(E12:AV12) -> 3439
B13: Squirrel Hill | D13: 7 | E13: 263 | F13: 333 | G13: 111 | H13: 37 | I13: 434 | J13: 340 | K13: 1843 | L13: 3122 | M13: 595 | N13: 679 | O13: 234 | P13: 1636 | Q13: 537 | R13: 130 | S13: 1001 | T13: 23 | U13: 133 | V13: 10 | W13: 105 | X13: 625 | Y13: 28 | Z13: 16 | AA13: 2 | AB13: 1 | AC13: 60 | AD13: 87 | AE13: 5 | AF13: 209 | AG13: 0 | AH13: 0 | AI13: 0 | AJ13: 0 | AK13: 0 | AL13: 0 | AM13: 0 | AN13: 0 | AO13: 0 | AP13: 0 | AQ13: 9 | AR13: 340 | AS13: 65 | AT13: 526 | AU13: 375 | AV13: 206 | AW13: =SUM(E13:AV13) -> 14120
B14: Oakland | D14: 8 | E14: 103 | F14: 132 | G14: 51 | H14: 15 | I14: 115 | J14: 52 | K14: 150 | L14: 2938 | M14: 220 | N14: 109 | O14: 29 | P14: 711 | Q14: 74 | R14: 47 | S14: 281 | T14: 6 | U14: 15 | V14: 0 | W14: 16 | X14: 60 | Y14: 3 | Z14: 1 | AA14: 1 | AB14: 0 | AC14: 9 | AD14: 13 | AE14: 4 | AF14: 76 | AG14: 0 | AH14: 0 | AI14: 0 | AJ14: 0 | AK14: 1 | AL14: 0 | AM14: 0 | AN14: 0 | AO14: 0 | AP14: 1 | AQ14: 1 | AR14: 188 | AS14: 9 | AT14: 58 | AU14: 149 | AV14: 74 | AW14: =SUM(E14:AV14) -> 5712
B15: South Side | D15: 9 | E15: 129 | F15: 179 | G15: 59 | H15: 17 | I15: 99 | J15: 57 | K15: 64 | L15: 611 | M15: 834 | N15: 42 | O15: 26 | P15: 964 | Q15: 31 | R15: 54 | S15: 171 | T15: 5 | U15: 7 | V15: 0 | W15: 9 | X15: 40 | Y15: 4 | Z15: 2 | AA15: 2 | AB15: 0 | AC15: 7 | AD15: 44 | AE15: 7 | AF15: 121 | AG15: 0 | AH15: 0 | AI15: 0 | AJ15: 0 | AK15: 0 | AL15: 0 | AM15: 0 | AN15: 0 | AO15: 0 | AP15: 1 | AQ15: 1 | AR15: 273 | AS15: 4 | AT15: 23 | AU15: 406 | AV15: 138 | AW15: =SUM(E15:AV15) -> 4431
B16: Shadyside | D16: 10 | E16: 74 | F16: 132 | G16: 64 | H16: 10 | I16: 221 | J16: 42 | K16: 245 | L16: 1334 | M16: 108 | N16: 532 | O16: 31 | P16: 440 | Q16: 336 | R16: 61 | S16: 650 | T16: 3 | U16: 45 | V16: 2 | W16: 21 | X16: 112 | Y16: 5 | Z16: 3 | AA16: 0 | AB16: 0 | AC16: 7 | AD16: 13 | AE16: 1 | AF16: 46 | AG16: 0 | AH16: 0 | AI16: 0 | AJ16: 0 | AK16: 0 | AL16: 0 | AM16: 0 | AN16: 0 | AO16: 0 | AP16: 0 | AQ16: 3 | AR16: 97 | AS16: 43 | AT16: 191 | AU16: 87 | AV16: 49 | AW16: =SUM(E16:AV16) -> 5008
B17: Waterfront (West Homestead Homestead Munhall(part)) | D17: 11 | E17: 50 | F17: 65 | G17: 18 | H17: 7 | I17: 65 | J17: 95 | K17: 148 | L17: 397 | M17: 131 | N17: 60 | O17: 657 | P17: 331 | Q17: 49 | R17: 20 | S17: 96 | T17: 31 | U17: 23 | V17: 2 | W17: 34 | X17: 178 | Y17: 24 | Z17: 25 | AA17: 4 | AB17: 1 | AC17: 130 | AD17: 104 | AE17: 12 | AF17: 44 | AG17: 0 | AH17: 0 | AI17: 0 | AJ17: 0 | AK17: 0 | AL17: 0 | AM17: 0 | AN17: 0 | AO17: 0 | AP17: 2 | AQ17: 4 | AR17: 60 | AS17: 7 | AT17: 49 | AU17: 122 | AV17: 68 | AW17: =SUM(E17:AV17) -> 3113
